Workbook

Sheet Общий
B2: Общий медиаплан
B3: Клиент: | F3: Всего экранов: | G3: =D32
B4: Бренд: | F4: Кол-во дней размещения: | G4: =D6-D5+1
B5: Начало РК: | D5: 45689 | F5: Показов всего за период: | G5: =АЗС!L12+'Азбука вкуса'!K12+Фитнес!K12+БЦ!K12+ТРЦ!K12+Автодор!K12+MetroCC!I14
B6: Окончание РК: | D6: 45716 | E6: OTS: | G6: =АЗС!L13+'Азбука вкуса'!K13+Фитнес!K13+БЦ!K13+ТРЦ!K13+Автодор!K13+MetroCC!I13
B7: Ролик1, сек: | D7: 15 | E7: CPT: | G7: =(D16-I29)/G6*1000
B8: Ролик2, сек: | F8: Предоставление ролика до: | G8: =D5-3
B9: Карта охвата (ALL): | D9: ССЫЛКА = > | E9: Оплата до: | G9: =D5-5
B10: Применяемые скидки (последовательно)
B11: За кол-во (средн): | D11: =(E22*F22+E23*F23+E24*F24+E25*F25+E26*F26+E27*F27+E29*F29)/E32
B12: За период: | D12: =SUBTOTAL(1,G22:G29)
B15: Стоимость размещения
B16: Всего, руб. NET: | D16: =I32 | CM16: 20% | EP16: 20%
B17: Всего, руб. GROSS: | D17: =J32 | CM17: 20% | EP17: 20%
CM18: 20% | EP18: 20%
B19: Расчет стоимости кампании | CM19: 20% | EP19: 20%
CM20: 20% | EP20: 20%
B21: № | C21: Площадки | D21: Количество | E21: Стоимость размещения по выбранной АП за период, без НДС | F21: Скидка за кол-во | G21: Скидка за период | H21: Итоговая скидка | I21: Стоимость c учетом всех скидок, без НДС | J21: Стоимость c учетом всех скидок, вкл. НДС | K21: Сумма НДС (20%) | L21: Фото | CM21: 20% | EP21: 20%
B22: 1 | C22: АЗС | D22: =АЗС!D88 | E22: =АЗС!F88 | F22: =АЗС!D11 | G22: =АЗС!D12 | H22: =SUBTOTAL(1,АЗС!J22:J85) | I22: =АЗС!K88 | J22: =АЗС!L88 | K22: =АЗС!M88 | L22: фото АЗС | CM22: 20% | EP22: 20%
B23: 2 | C23: Азбука Вкуса | D23: ='Азбука вкуса'!D26 | E23: ='Азбука вкуса'!F26 | F23: ='Азбука вкуса'!D11 | G23: ='Азбука вкуса'!D12 | H23: =SUBTOTAL(1,'Азбука вкуса'!I22:I24) | I23: ='Азбука вкуса'!J26 | J23: ='Азбука вкуса'!K26 | K23: ='Азбука вкуса'!L26 | L23: фото Азбука вкуса | CM23: 20% | EP23: 20%
B24: 3 | C24: Metro C&C | D24: =MetroCC!I4 | E24: =MetroCC!F40 | F24: =MetroCC!D10 | G24: =MetroCC!D11 | H24: =MetroCC!D14 | I24: =MetroCC!D16 | J24: =MetroCC!D17 | K24: =MetroCC!I40 | CM24: 20% | EP24: 20%
B25: 4 | C25: Фитнес центры | D25: =Фитнес!D38 | E25: =Фитнес!F38 | F25: =Фитнес!D11 | G25: =Фитнес!D12 | H25: =SUBTOTAL(1,Фитнес!I22:I36) | I25: =Фитнес!J38 | J25: =Фитнес!K38 | K25: =Фитнес!L38 | CM25: 20% | EP25: 20%
B26: 5 | C26: БЦ | D26: =БЦ!D25 | E26: =БЦ!F25 | F26: =БЦ!D11 | G26: =БЦ!D12 | H26: =SUBTOTAL(1,БЦ!I22:I23) | I26: =БЦ!J25 | J26: =БЦ!K25 | K26: =БЦ!L25 | CM26: 20% | EP26: 20%
B27: 6 | C27: ТРЦ | D27: =ТРЦ!K3 | E27: =ТРЦ!F28 | F27: =ТРЦ!D11 | G27: =ТРЦ!D12 | H27: =SUBTOTAL(1,ТРЦ!I24:I26) | I27: =ТРЦ!D16 | J27: =ТРЦ!D17 | K27: =ТРЦ!L28 | CM27: 20% | EP27: 20%
B28: 7 | C28: Афимолл Центр. атриум | D28: ='Афимолл - Цетральный атриум'!J3 | E28: ='Афимолл - Цетральный атриум'!F22 | F28: 0 | G28: 0 | H28: ='Афимолл - Цетральный атриум'!G22 | I28: ='Афимолл - Цетральный атриум'!H22 | J28: ='Афимолл - Цетральный атриум'!I22 | K28: ='Афимолл - Цетральный атриум'!J22 | CM28: 20% | EP28: 20%
B29: 8 | C29: Wifi аналитика | D29: ='Wi-Fi'!D36 | E29: ='Wi-Fi'!E36 | F29: ='Wi-Fi'!D11 | G29: ='Wi-Fi'!D12 | H29: =SUBTOTAL(1,'Wi-Fi'!H22:H34) | I29: ='Wi-Fi'!D16 | J29: ='Wi-Fi'!D17 | K29: ='Wi-Fi'!K36 | CM29: 20% | EP29: 20%
B30: 9 | C30: Радио | D30: =Радио!D25 | E30: =Радио!F25 | F30: =Радио!D11 | G30: 0 | H30: =Радио!D11 | I30: =Радио!I25 | J30: =Радио!J25 | K30: =Радио!K25 | CM30: 20% | EP30: 20%
CM31: 20% | EP31: 20%
D32: =SUM(D22:D29) | E32: =SUM(E22:E30) | I32: =SUM(I22:I30) | J32: =SUM(J22:J30) | K32: =SUM(K22:K30) | CM32: 20% | EP32: 20%
CM33: 20% | EP33: 20%
B34: Скачать описание целевой аудитории | CM34: 20% | EP34: 20%
CM35: 20% | EP35: 20%
B36: Скачать технические требования | CM36: 20% | EP36: 20%
CM37: 20% | EP37: 20%
B38: Скачать информацию по предоставлению фотоотчетов | CM38: 20% | EP38: 20%

Sheet АЗС
B2: Сети АЗС | AO2: ПК | AP2: 0
B3: Клиент: | J3: Всего экранов: | L3: =D88 | AO3: РА | AP3: 0.05 | AQ3: Доп скидка
B4: Бренд: | J4: Часов работы одного экрана в сутки: | L4: 24 | AP4: 0.1 | AQ4: Welcome скидка
B5: Начало РК: | D5: =Общий!D5 | J5: Продолжительность блока в минутах: | L5: 3 | AP5: 0.15 | AQ5: Сезонная скидка
B6: Окончание РК: | D6: =Общий!D6 | J6: Блоков в сутки на одном экране: | L6: =L4*60/L5 | AP6: 0.2
B7: Ролик1, сек: | D7: =Общий!D7 | J7: Кол-во дней размещения: | L7: =D6-D5+1 | AP7: 0.25
B8: Ролик2, сек: | J8: Кол-во роликов в блоке: | L8: =COUNT(D$7,D$8,D$9)
B9: Карта охвата (ALL) | D9: фото АЗС | J9: Итого секунд в блоке: | L9: =SUM(D7:D9)
B10: Применяемые скидки (последовательно) | J10: Показов в день на одном экране: | L10: =L6*L8 | AP10: 0
B11: За кол-во экранов(средн): | D11: =SUBTOTAL(1,G22:G85) | J11: Минут в день на одном экране: | L11: =L6*L9/60 | AP11: 0.05
B12: За период: | D12: =IF(L7>69,'Цены|Скидки'!$C$100,IF(L7>39,'Цены|Скидки'!$C$99,0%)) | J12: Показов на всех экранах за период: | L12: =L10*L7*L3 | AP12: 0.1
B13: =IF(AC2="РА","Скидка для РА:"," ") | D13: =IF(AC2="РА",AD2," ") | J13: OTS: | L13: =N88 | AP13: 0.15
B14: =IF(AC3=0," ",AC3) | D14: =IF(OR(AC3="Доп скидка",AC3="Сезонная скидка",AC3="Welcome скидка")=TRUE,AD3," ") | J14: CPT: | L14: =O88 | AP14: 0.2
B15: Стоимость размещения | J15: % предоставляемого фотоотчета: | AP15: 0.25
B16: Всего, руб. NET: | D16: =K88 | J16: Предоставление ролика до: | L16: =D5-3
B17: Всего, руб. GROSS: | D17: =L88 | J17: Оплата до: | L17: =D5-5
AO18: Автобренд
B19: Расчет стоимости кампании на АЗС
B21: Регион | C21: Сеть | D21: Количество экранов | E21: Стоимость размещения в сутки на одном экране, без НДС | F21: Стоимость размещения по выбранной АП за период, без НДС | G21: Скидка за кол-во экранов | H21: Скидка за период | I21: Скидка за кол-во регионов | J21: Итоговая скидка | K21: Стоимость c учетом всех скидок, без НДС | L21: Стоимость c учетом всех скидок, вкл. НДС | M21: Сумма НДС (20%) | N21: OTS | O21: CPT
B22: Москва | C22: Роснефть | D22: =IF(C22="АЗС",SUMIFS('Адресная программа'!$O$20:$O$4940,'Адресная программа'!$L$20:$L$4940,1,'Адресная программа'!$C$20:$C$4940,АЗС!B22,'Адресная программа'!$F$20:$F$4940,"АЗС",'Адресная программа'!$G$20:$G$4940,"<>Газпромнефть"),SUMIFS('Адресная программа'!$O$20:$O$4940,'Адресная программа'!$L$20:$L$4940,1,'Адресная программа'!$C$20:$C$4940,АЗС!B22,'Адресная программа'!$G$20:$G$4940,АЗС!C22,'Адресная программа'!$F$20:$F$4940,"АЗС")) | E22: ='Цены|Скидки'!$D$11/15*$L$9 | F22: =E22*$L$7*D22 | G22: =IF(SUM($D$22:$D$23)=SUMIFS('Адресная программа'!$K$20:$K$4940,'Адресная программа'!$L$20:$L$4940,1,'Адресная программа'!$C$20:$C$4940,АЗС!B22,'Адресная программа'!$G$20:$G$4940,"<>Газпромнефть",'Адресная программа'!$F$20:$F$4940,"АЗС"),'Цены|Скидки'!$C$31,IF(SUM($D$22:$D$23)>=(SUMIFS('Адресная программа'!$K$20:$K$4940,'Адресная программа'!$L$20:$L$4940,1,'Адресная программа'!$C$20:$C$4940,АЗС!B22,'Адресная программа'!$G$20:$G$4940,"<>Газпромнефть",'Адресная программа'!$F$20:$F$4940,"АЗС")*'Цены|Скидки'!$B$32),'Цены|Скидки'!$C$32,IF(SUM($D$22:$D$23)>=(SUMIFS('Адресная программа'!$K$20:$K$4940,'Адресная программа'!$L$20:$L$4940,1,'Адресная программа'!$C$20:$C$4940,АЗС!B22,'Адресная программа'!$G$20:$G$4940,"<>Газпромнефть",'Адресная программа'!$F$20:$F$4940,"АЗС")*'Цены|Скидки'!$B$33),'Цены|Скидки'!$C$33,IF(SUM($D$22:$D$23)>=(SUMIFS('Адресная программа'!$K$20:$K$4940,'Адресная программа'!$L$20:$L$4940,1,'Адресная программа'!$C$20:$C$4940,АЗС!B22,'Адресная программа'!$G$20:$G$4940,"<>Газпромнефть",'Адресная программа'!$F$20:$F$4940,"АЗС")*'Цены|Скидки'!$B$34),'Цены|Скидки'!$C$34,IF(SUM($D$22:$D$23)>=(SUMIFS('Адресная программа'!$K$20:$K$4940,'Адресная программа'!$L$20:$L$4940,1,'Адресная программа'!$C$20:$C$4940,АЗС!B22,'Адресная программа'!$G$20:$G$4940,"<>Газпромнефть",'Адресная программа'!$F$20:$F$4940,"АЗС")*'Цены|Скидки'!$B$35),'Цены|Скидки'!$C$35,IF(SUM($D$22:$D$23)>=(SUMIFS('Адресная программа'!$K$20:$K$4940,'Адресная программа'!$L$20:$L$4940,1,'Адресная программа'!$C$20:$C$4940,АЗС!B22,'Адресная программа'!$G$20:$G$4940,"<>Газпромнефть",'Адресная программа'!$F$20:$F$4940,"АЗС")*'Цены|Скидки'!$B$36),'Цены|Скидки'!$C$36,0%)))))) | H22: =$D$12 | J22: =IF(SUM($D$22:$D$23)=0,0,1-SUM($K$22:$K$23)/SUM($F$22:$F$23)) | K22: =F22*(1-G22)*(1-H22)*(1-IF($AC$2="РА",$AD$2,0))*(1-IF(OR($AC$3="Доп скидка",$AC$3="Сезонная скидка",$AC$3="Welcome скидка")=TRUE,$AD$3,0)) | L22: =K22+M22 | M22: =K22*0.2 | N22: =D22*$L$7*1210 | O22: =IF(N22=0,0,(K22/N22*1000)/$D$7*10)
B23: Москва | C23: Нефтьмагистраль | D23: =IF(C23="АЗС",SUMIFS('Адресная программа'!$O$20:$O$4940,'Адресная программа'!$L$20:$L$4940,1,'Адресная программа'!$C$20:$C$4940,АЗС!B23,'Адресная программа'!$F$20:$F$4940,"АЗС",'Адресная программа'!$G$20:$G$4940,"<>Газпромнефть"),SUMIFS('Адресная программа'!$O$20:$O$4940,'Адресная программа'!$L$20:$L$4940,1,'Адресная программа'!$C$20:$C$4940,АЗС!B23,'Адресная программа'!$G$20:$G$4940,АЗС!C23,'Адресная программа'!$F$20:$F$4940,"АЗС")) | E23: ='Цены|Скидки'!$D$11/15*$L$9 | F23: =E23*$L$7*D23 | G23: =IF(SUM($D$22:$D$23)=SUMIFS('Адресная программа'!$K$20:$K$4940,'Адресная программа'!$L$20:$L$4940,1,'Адресная программа'!$C$20:$C$4940,АЗС!B23,'Адресная программа'!$G$20:$G$4940,"<>Газпромнефть",'Адресная программа'!$F$20:$F$4940,"АЗС"),'Цены|Скидки'!$C$31,IF(SUM($D$22:$D$23)>=(SUMIFS('Адресная программа'!$K$20:$K$4940,'Адресная программа'!$L$20:$L$4940,1,'Адресная программа'!$C$20:$C$4940,АЗС!B23,'Адресная программа'!$G$20:$G$4940,"<>Газпромнефть",'Адресная программа'!$F$20:$F$4940,"АЗС")*'Цены|Скидки'!$B$32),'Цены|Скидки'!$C$32,IF(SUM($D$22:$D$23)>=(SUMIFS('Адресная программа'!$K$20:$K$4940,'Адресная программа'!$L$20:$L$4940,1,'Адресная программа'!$C$20:$C$4940,АЗС!B23,'Адресная программа'!$G$20:$G$4940,"<>Газпромнефть",'Адресная программа'!$F$20:$F$4940,"АЗС")*'Цены|Скидки'!$B$33),'Цены|Скидки'!$C$33,IF(SUM($D$22:$D$23)>=(SUMIFS('Адресная программа'!$K$20:$K$4940,'Адресная программа'!$L$20:$L$4940,1,'Адресная программа'!$C$20:$C$4940,АЗС!B23,'Адресная программа'!$G$20:$G$4940,"<>Газпромнефть",'Адресная программа'!$F$20:$F$4940,"АЗС")*'Цены|Скидки'!$B$34),'Цены|Скидки'!$C$34,IF(SUM($D$22:$D$23)>=(SUMIFS('Адресная программа'!$K$20:$K$4940,'Адресная программа'!$L$20:$L$4940,1,'Адресная программа'!$C$20:$C$4940,АЗС!B23,'Адресная программа'!$G$20:$G$4940,"<>Газпромнефть",'Адресная программа'!$F$20:$F$4940,"АЗС")*'Цены|Скидки'!$B$35),'Цены|Скидки'!$C$35,IF(SUM($D$22:$D$23)>=(SUMIFS('Адресная программа'!$K$20:$K$4940,'Адресная программа'!$L$20:$L$4940,1,'Адресная программа'!$C$20:$C$4940,АЗС!B23,'Адресная программа'!$G$20:$G$4940,"<>Газпромнефть",'Адресная программа'!$F$20:$F$4940,"АЗС")*'Цены|Скидки'!$B$36),'Цены|Скидки'!$C$36,0%)))))) | H23: =$D$12 | J23: =IF(SUM($D$22:$D$23)=0,0,1-SUM($K$22:$K$23)/SUM($F$22:$F$23)) | K23: =F23*(1-G23)*(1-H23)*(1-IF($AC$2="РА",$AD$2,0))*(1-IF(OR($AC$3="Доп скидка",$AC$3="Сезонная скидка",$AC$3="Welcome скидка")=TRUE,$AD$3,0)) | L23: =K23+M23 | M23: =K23*0.2 | N23: =D23*$L$7*1210 | O23: =IF(N23=0,0,(K23/N23*1000)/$D$7*10)
B24: Москва | C24: Газпромнефть | D24: =IF(C24="АЗС",SUMIFS('Адресная программа'!$O$20:$O$4940,'Адресная программа'!$L$20:$L$4940,1,'Адресная программа'!$C$20:$C$4940,АЗС!B24,'Адресная программа'!$F$20:$F$4940,"АЗС",'Адресная программа'!$G$20:$G$4940,"<>Газпромнефть"),SUMIFS('Адресная программа'!$O$20:$O$4940,'Адресная программа'!$L$20:$L$4940,1,'Адресная программа'!$C$20:$C$4940,АЗС!B24,'Адресная программа'!$G$20:$G$4940,АЗС!C24,'Адресная программа'!$F$20:$F$4940,"АЗС")) | E24: ='Цены|Скидки'!G11/15*$L$9 | F24: =E24*$L$7*D24 | G24: =IF(D24=SUMIFS('Адресная программа'!$K$20:$K$4940,'Адресная программа'!$L$20:$L$4940,1,'Адресная программа'!$C$20:$C$4940,АЗС!B24,'Адресная программа'!$G$20:$G$4940,"=Газпромнефть",'Адресная программа'!$F$20:$F$4940,"АЗС"),'Цены|Скидки'!$C$43,IF(D24>=(SUMIFS('Адресная программа'!$K$20:$K$4940,'Адресная программа'!$L$20:$L$4940,1,'Адресная программа'!$C$20:$C$4940,АЗС!B24,'Адресная программа'!$G$20:$G$4940,"=Газпромнефть",'Адресная программа'!$F$20:$F$4940,"АЗС")*'Цены|Скидки'!$B$44),'Цены|Скидки'!$C$44,IF(D24>=(SUMIFS('Адресная программа'!$K$20:$K$4940,'Адресная программа'!$L$20:$L$4940,1,'Адресная программа'!$C$20:$C$4940,АЗС!B24,'Адресная программа'!$G$20:$G$4940,"=Газпромнефть",'Адресная программа'!$F$20:$F$4940,"АЗС")*'Цены|Скидки'!$B$45),'Цены|Скидки'!$C$45,IF(D24>=(SUMIFS('Адресная программа'!$K$20:$K$4940,'Адресная программа'!$L$20:$L$4940,1,'Адресная программа'!$C$20:$C$4940,АЗС!B24,'Адресная программа'!$G$20:$G$4940,"=Газпромнефть",'Адресная программа'!$F$20:$F$4940,"АЗС")*'Цены|Скидки'!$B$46),'Цены|Скидки'!$C$46,0%)))) | H24: =$D$12 | I24: ='Адресная программа'!Y19 | J24: =IF(D24=0,0,1-K24/F24) | K24: =F24*(1-G24)*(1-H24)*(1-IF($AC$2="РА",$AD$2,0))*(1-IF(OR($AC$3="Доп скидка",$AC$3="Сезонная скидка",$AC$3="Welcome скидка")=TRUE,$AD$3,0))*(1-'Адресная программа'!Y19) | L24: =K24+M24 | M24: =K24*0.2 | N24: =D24*$L$7*1485 | O24: =IF(N24=0,0,(K24/N24*1000)/$D$7*10)
B25: Санкт-Петербург | C25: Роснефть | D25: =IF(C25="АЗС",SUMIFS('Адресная программа'!$O$20:$O$4940,'Адресная программа'!$L$20:$L$4940,1,'Адресная программа'!$C$20:$C$4940,АЗС!B25,'Адресная программа'!$F$20:$F$4940,"АЗС",'Адресная программа'!$G$20:$G$4940,"<>Газпромнефть"),SUMIFS('Адресная программа'!$O$20:$O$4940,'Адресная программа'!$L$20:$L$4940,1,'Адресная программа'!$C$20:$C$4940,АЗС!B25,'Адресная программа'!$G$20:$G$4940,АЗС!C25,'Адресная программа'!$F$20:$F$4940,"АЗС")) | E25: ='Цены|Скидки'!$E$11/15*$L$9 | F25: =E25*$L$7*D25 | G25: =IF(SUM($D$25:$D$25)=SUMIFS('Адресная программа'!$K$20:$K$4940,'Адресная программа'!$L$20:$L$4940,1,'Адресная программа'!$C$20:$C$4940,АЗС!B25,'Адресная программа'!$G$20:$G$4940,"<>Газпромнефть",'Адресная программа'!$F$20:$F$4940,"АЗС"),'Цены|Скидки'!$C$31,IF(SUM($D$25:$D$25)>=(SUMIFS('Адресная программа'!$K$20:$K$4940,'Адресная программа'!$L$20:$L$4940,1,'Адресная программа'!$C$20:$C$4940,АЗС!B25,'Адресная программа'!$G$20:$G$4940,"<>Газпромнефть",'Адресная программа'!$F$20:$F$4940,"АЗС")*'Цены|Скидки'!$B$32),'Цены|Скидки'!$C$32,IF(SUM($D$25:$D$25)>=(SUMIFS('Адресная программа'!$K$20:$K$4940,'Адресная программа'!$L$20:$L$4940,1,'Адресная программа'!$C$20:$C$4940,АЗС!B25,'Адресная программа'!$G$20:$G$4940,"<>Газпромнефть",'Адресная программа'!$F$20:$F$4940,"АЗС")*'Цены|Скидки'!$B$33),'Цены|Скидки'!$C$33,IF(SUM($D$25:$D$25)>=(SUMIFS('Адресная программа'!$K$20:$K$4940,'Адресная программа'!$L$20:$L$4940,1,'Адресная программа'!$C$20:$C$4940,АЗС!B25,'Адресная программа'!$G$20:$G$4940,"<>Газпромнефть",'Адресная программа'!$F$20:$F$4940,"АЗС")*'Цены|Скидки'!$B$34),'Цены|Скидки'!$C$34,IF(SUM($D$25:$D$25)>=(SUMIFS('Адресная программа'!$K$20:$K$4940,'Адресная программа'!$L$20:$L$4940,1,'Адресная программа'!$C$20:$C$4940,АЗС!B25,'Адресная программа'!$G$20:$G$4940,"<>Газпромнефть",'Адресная программа'!$F$20:$F$4940,"АЗС")*'Цены|Скидки'!$B$35),'Цены|Скидки'!$C$35,IF(SUM($D$25:$D$25)>=(SUMIFS('Адресная программа'!$K$20:$K$4940,'Адресная программа'!$L$20:$L$4940,1,'Адресная программа'!$C$20:$C$4940,АЗС!B25,'Адресная программа'!$G$20:$G$4940,"<>Газпромнефть",'Адресная программа'!$F$20:$F$4940,"АЗС")*'Цены|Скидки'!$B$36),'Цены|Скидки'!$C$36,0%)))))) | H25: =$D$12 | J25: =IF(SUM($D$25:$D$25)=0,0,1-SUM($K$25:$K$25)/SUM($F$25:$F$25)) | K25: =F25*(1-G25)*(1-H25)*(1-IF($AC$2="РА",$AD$2,0))*(1-IF(OR($AC$3="Доп скидка",$AC$3="Сезонная скидка",$AC$3="Welcome скидка")=TRUE,$AD$3,0)) | L25: =K25+M25 | M25: =K25*0.2 | N25: =D25*$L$7*1210 | O25: =IF(N25=0,0,(K25/N25*1000)/$D$7*10)
B26: Санкт-Петербург | C26: Газпромнефть | D26: =IF(C26="АЗС",SUMIFS('Адресная программа'!$O$20:$O$4940,'Адресная программа'!$L$20:$L$4940,1,'Адресная программа'!$C$20:$C$4940,АЗС!B26,'Адресная программа'!$F$20:$F$4940,"АЗС",'Адресная программа'!$G$20:$G$4940,"<>Газпромнефть"),SUMIFS('Адресная программа'!$O$20:$O$4940,'Адресная программа'!$L$20:$L$4940,1,'Адресная программа'!$C$20:$C$4940,АЗС!B26,'Адресная программа'!$G$20:$G$4940,АЗС!C26,'Адресная программа'!$F$20:$F$4940,"АЗС")) | E26: ='Цены|Скидки'!H11/15*$L$9 | F26: =E26*$L$7*D26 | G26: =IF(D26=SUMIFS('Адресная программа'!$K$20:$K$4940,'Адресная программа'!$L$20:$L$4940,1,'Адресная программа'!$C$20:$C$4940,АЗС!B26,'Адресная программа'!$G$20:$G$4940,"=Газпромнефть",'Адресная программа'!$F$20:$F$4940,"АЗС"),'Цены|Скидки'!$C$43,IF(D26>=(SUMIFS('Адресная программа'!$K$20:$K$4940,'Адресная программа'!$L$20:$L$4940,1,'Адресная программа'!$C$20:$C$4940,АЗС!B26,'Адресная программа'!$G$20:$G$4940,"=Газпромнефть",'Адресная программа'!$F$20:$F$4940,"АЗС")*'Цены|Скидки'!$B$44),'Цены|Скидки'!$C$44,IF(D26>=(SUMIFS('Адресная программа'!$K$20:$K$4940,'Адресная программа'!$L$20:$L$4940,1,'Адресная программа'!$C$20:$C$4940,АЗС!B26,'Адресная программа'!$G$20:$G$4940,"=Газпромнефть",'Адресная программа'!$F$20:$F$4940,"АЗС")*'Цены|Скидки'!$B$45),'Цены|Скидки'!$C$45,IF(D26>=(SUMIFS('Адресная программа'!$K$20:$K$4940,'Адресная программа'!$L$20:$L$4940,1,'Адресная программа'!$C$20:$C$4940,АЗС!B26,'Адресная программа'!$G$20:$G$4940,"=Газпромнефть",'Адресная программа'!$F$20:$F$4940,"АЗС")*'Цены|Скидки'!$B$46),'Цены|Скидки'!$C$46,0%)))) | H26: =$D$12 | I26: ='Адресная программа'!Y19 | J26: =IF(D26=0,0,1-K26/F26) | K26: =F26*(1-G26)*(1-H26)*(1-IF($AC$2="РА",$AD$2,0))*(1-IF(OR($AC$3="Доп скидка",$AC$3="Сезонная скидка",$AC$3="Welcome скидка")=TRUE,$AD$3,0))*(1-'Адресная программа'!Y19) | L26: =K26+M26 | M26: =K26*0.2 | N26: =D26*$L$7*1375 | O26: =IF(N26=0,0,(K26/N26*1000)/$D$7*10)
B27: Архангельск | C27: Роснефть | D27: =IF(C27="АЗС",SUMIFS('Адресная программа'!$O$20:$O$4940,'Адресная программа'!$L$20:$L$4940,1,'Адресная программа'!$C$20:$C$4940,АЗС!B27,'Адресная программа'!$F$20:$F$4940,"АЗС",'Адресная программа'!$G$20:$G$4940,"<>Газпромнефть"),SUMIFS('Адресная программа'!$O$20:$O$4940,'Адресная программа'!$L$20:$L$4940,1,'Адресная программа'!$C$20:$C$4940,АЗС!B27,'Адресная программа'!$G$20:$G$4940,АЗС!C27,'Адресная программа'!$F$20:$F$4940,"АЗС")) | E27: ='Цены|Скидки'!$F$11/15*$L$9 | F27: =E27*$L$7*D27 | G27: =IF(D27=SUMIFS('Адресная программа'!$K$20:$K$4940,'Адресная программа'!$L$20:$L$4940,1,'Адресная программа'!$C$20:$C$4940,АЗС!B27,'Адресная программа'!$G$20:$G$4940,"<>Газпромнефть",'Адресная программа'!$F$20:$F$4940,"АЗС"),'Цены|Скидки'!$C$31,IF(D27>=(SUMIFS('Адресная программа'!$K$20:$K$4940,'Адресная программа'!$L$20:$L$4940,1,'Адресная программа'!$C$20:$C$4940,АЗС!B27,'Адресная программа'!$G$20:$G$4940,"<>Газпромнефть",'Адресная программа'!$F$20:$F$4940,"АЗС")*'Цены|Скидки'!$B$32),'Цены|Скидки'!$C$32,IF(D27>=(SUMIFS('Адресная программа'!$K$20:$K$4940,'Адресная программа'!$L$20:$L$4940,1,'Адресная программа'!$C$20:$C$4940,АЗС!B27,'Адресная программа'!$G$20:$G$4940,"<>Газпромнефть",'Адресная программа'!$F$20:$F$4940,"АЗС")*'Цены|Скидки'!$B$33),'Цены|Скидки'!$C$33,IF(D27>=(SUMIFS('Адресная программа'!$K$20:$K$4940,'Адресная программа'!$L$20:$L$4940,1,'Адресная программа'!$C$20:$C$4940,АЗС!B27,'Адресная программа'!$G$20:$G$4940,"<>Газпромнефть",'Адресная программа'!$F$20:$F$4940,"АЗС")*'Цены|Скидки'!$B$34),'Цены|Скидки'!$C$34,0%)))) | H27: =D$12 | J27: =IF(D27=0,0,1-K27/F27) | K27: =F27*(1-G27)*(1-H27)*(1-IF($AC$2="РА",$AD$2,0))*(1-IF(OR($AC$3="Доп скидка",$AC$3="Сезонная скидка",$AC$3="Welcome скидка")=TRUE,$AD$3,0)) | L27: =K27+M27 | M27: =K27*0.2 | N27: =D27*L$7*1045 | O27: =IF(N27=0,0,(K27/N27*1000)/$D$7*10)
B28: Абхазия | C28: Подорожник | D28: =IF(C28="АЗС",SUMIFS('Адресная программа'!$O$20:$O$4940,'Адресная программа'!$L$20:$L$4940,1,'Адресная программа'!$C$20:$C$4940,АЗС!B28,'Адресная программа'!$F$20:$F$4940,"АЗС",'Адресная программа'!$G$20:$G$4940,"<>Газпромнефть"),SUMIFS('Адресная программа'!$O$20:$O$4940,'Адресная программа'!$L$20:$L$4940,1,'Адресная программа'!$C$20:$C$4940,АЗС!B28,'Адресная программа'!$G$20:$G$4940,АЗС!C28,'Адресная программа'!$F$20:$F$4940,"АЗС")) | E28: ='Цены|Скидки'!$F$11/15*$L$9 | F28: =E28*$L$7*D28 | G28: =IF(D28=SUMIFS('Адресная программа'!$K$20:$K$4940,'Адресная программа'!$L$20:$L$4940,1,'Адресная программа'!$C$20:$C$4940,АЗС!B28,'Адресная программа'!$G$20:$G$4940,"<>Газпромнефть",'Адресная программа'!$F$20:$F$4940,"АЗС"),'Цены|Скидки'!$C$31,IF(D28>=(SUMIFS('Адресная программа'!$K$20:$K$4940,'Адресная программа'!$L$20:$L$4940,1,'Адресная программа'!$C$20:$C$4940,АЗС!B28,'Адресная программа'!$G$20:$G$4940,"<>Газпромнефть",'Адресная программа'!$F$20:$F$4940,"АЗС")*'Цены|Скидки'!$B$32),'Цены|Скидки'!$C$32,IF(D28>=(SUMIFS('Адресная программа'!$K$20:$K$4940,'Адресная программа'!$L$20:$L$4940,1,'Адресная программа'!$C$20:$C$4940,АЗС!B28,'Адресная программа'!$G$20:$G$4940,"<>Газпромнефть",'Адресная программа'!$F$20:$F$4940,"АЗС")*'Цены|Скидки'!$B$33),'Цены|Скидки'!$C$33,IF(D28>=(SUMIFS('Адресная программа'!$K$20:$K$4940,'Адресная программа'!$L$20:$L$4940,1,'Адресная программа'!$C$20:$C$4940,АЗС!B28,'Адресная программа'!$G$20:$G$4940,"<>Газпромнефть",'Адресная программа'!$F$20:$F$4940,"АЗС")*'Цены|Скидки'!$B$34),'Цены|Скидки'!$C$34,0%)))) | H28: =D$12 | J28: =IF(D28=0,0,1-K28/F28) | K28: =F28*(1-G28)*(1-H28)*(1-IF($AC$2="РА",$AD$2,0))*(1-IF(OR($AC$3="Доп скидка",$AC$3="Сезонная скидка",$AC$3="Welcome скидка")=TRUE,$AD$3,0)) | L28: =K28+M28 | M28: =K28*0.2 | N28: =D28*L$7*1045 | O28: =IF(N28=0,0,(K28/N28*1000)/$D$7*10)
B29: Алтайский край | C29: Роснефть | D29: =IF(C29="АЗС",SUMIFS('Адресная программа'!$O$20:$O$4940,'Адресная программа'!$L$20:$L$4940,1,'Адресная программа'!$C$20:$C$4940,АЗС!B29,'Адресная программа'!$F$20:$F$4940,"АЗС",'Адресная программа'!$G$20:$G$4940,"<>Газпромнефть"),SUMIFS('Адресная программа'!$O$20:$O$4940,'Адресная программа'!$L$20:$L$4940,1,'Адресная программа'!$C$20:$C$4940,АЗС!B29,'Адресная программа'!$G$20:$G$4940,АЗС!C29,'Адресная программа'!$F$20:$F$4940,"АЗС")) | E29: ='Цены|Скидки'!$F$11/15*$L$9 | F29: =E29*$L$7*D29 | G29: =IF(D29=SUMIFS('Адресная программа'!$K$20:$K$4940,'Адресная программа'!$L$20:$L$4940,1,'Адресная программа'!$C$20:$C$4940,АЗС!B29,'Адресная программа'!$G$20:$G$4940,"<>Газпромнефть",'Адресная программа'!$F$20:$F$4940,"АЗС"),'Цены|Скидки'!$C$31,IF(D29>=(SUMIFS('Адресная программа'!$K$20:$K$4940,'Адресная программа'!$L$20:$L$4940,1,'Адресная программа'!$C$20:$C$4940,АЗС!B29,'Адресная программа'!$G$20:$G$4940,"<>Газпромнефть",'Адресная программа'!$F$20:$F$4940,"АЗС")*'Цены|Скидки'!$B$32),'Цены|Скидки'!$C$32,IF(D29>=(SUMIFS('Адресная программа'!$K$20:$K$4940,'Адресная программа'!$L$20:$L$4940,1,'Адресная программа'!$C$20:$C$4940,АЗС!B29,'Адресная программа'!$G$20:$G$4940,"<>Газпромнефть",'Адресная программа'!$F$20:$F$4940,"АЗС")*'Цены|Скидки'!$B$33),'Цены|Скидки'!$C$33,IF(D29>=(SUMIFS('Адресная программа'!$K$20:$K$4940,'Адресная программа'!$L$20:$L$4940,1,'Адресная программа'!$C$20:$C$4940,АЗС!B29,'Адресная программа'!$G$20:$G$4940,"<>Газпромнефть",'Адресная программа'!$F$20:$F$4940,"АЗС")*'Цены|Скидки'!$B$34),'Цены|Скидки'!$C$34,0%)))) | H29: =D$12 | J29: =IF(D29=0,0,1-K29/F29) | K29: =F29*(1-G29)*(1-H29)*(1-IF($AC$2="РА",$AD$2,0))*(1-IF(OR($AC$3="Доп скидка",$AC$3="Сезонная скидка",$AC$3="Welcome скидка")=TRUE,$AD$3,0)) | L29: =K29+M29 | M29: =K29*0.2 | N29: =D29*$L$7*1210 | O29: =IF(N29=0,0,(K29/N29*1000)/$D$7*10)
B30: Алтайский край | C30: Газпромнефть | D30: =IF(C30="АЗС",SUMIFS('Адресная программа'!$O$20:$O$4940,'Адресная программа'!$L$20:$L$4940,1,'Адресная программа'!$C$20:$C$4940,АЗС!B30,'Адресная программа'!$F$20:$F$4940,"АЗС",'Адресная программа'!$G$20:$G$4940,"<>Газпромнефть"),SUMIFS('Адресная программа'!$O$20:$O$4940,'Адресная программа'!$L$20:$L$4940,1,'Адресная программа'!$C$20:$C$4940,АЗС!B30,'Адресная программа'!$G$20:$G$4940,АЗС!C30,'Адресная программа'!$F$20:$F$4940,"АЗС")) | E30: ='Цены|Скидки'!$I$11/15*$L$9 | F30: =E30*$L$7*D30 | G30: =IF(D30=SUMIFS('Адресная программа'!$K$20:$K$4940,'Адресная программа'!$L$20:$L$4940,1,'Адресная программа'!$C$20:$C$4940,АЗС!B30,'Адресная программа'!$G$20:$G$4940,"=Газпромнефть",'Адресная программа'!$F$20:$F$4940,"АЗС"),'Цены|Скидки'!$C$43,IF(D30>=(SUMIFS('Адресная программа'!$K$20:$K$4940,'Адресная программа'!$L$20:$L$4940,1,'Адресная программа'!$C$20:$C$4940,АЗС!B30,'Адресная программа'!$G$20:$G$4940,"=Газпромнефть",'Адресная программа'!$F$20:$F$4940,"АЗС")*'Цены|Скидки'!$B$44),'Цены|Скидки'!$C$44,IF(D30>=(SUMIFS('Адресная программа'!$K$20:$K$4940,'Адресная программа'!$L$20:$L$4940,1,'Адресная программа'!$C$20:$C$4940,АЗС!B30,'Адресная программа'!$G$20:$G$4940,"=Газпромнефть",'Адресная программа'!$F$20:$F$4940,"АЗС")*'Цены|Скидки'!$B$45),'Цены|Скидки'!$C$45,IF(D30>=(SUMIFS('Адресная программа'!$K$20:$K$4940,'Адресная программа'!$L$20:$L$4940,1,'Адресная программа'!$C$20:$C$4940,АЗС!B30,'Адресная программа'!$G$20:$G$4940,"=Газпромнефть",'Адресная программа'!$F$20:$F$4940,"АЗС")*'Цены|Скидки'!$B$46),'Цены|Скидки'!$C$46,0%)))) | H30: =$D$12 | I30: ='Адресная программа'!Y19 | J30: =IF(D30=0,0,1-K30/F30) | K30: =F30*(1-G30)*(1-H30)*(1-IF($AC$2="РА",$AD$2,0))*(1-IF(OR($AC$3="Доп скидка",$AC$3="Сезонная скидка",$AC$3="Welcome скидка")=TRUE,$AD$3,0))*(1-'Адресная программа'!Y19) | L30: =K30+M30 | M30: =K30*0.2 | N30: =D30*$L$7*1210 | O30: =IF(N30=0,0,(K30/N30*1000)/$D$7*10)
B31: Белгород | C31: Роснефть | D31: =IF(C31="АЗС",SUMIFS('Адресная программа'!$O$20:$O$4940,'Адресная программа'!$L$20:$L$4940,1,'Адресная программа'!$C$20:$C$4940,АЗС!B31,'Адресная программа'!$F$20:$F$4940,"АЗС",'Адресная программа'!$G$20:$G$4940,"<>Газпромнефть"),SUMIFS('Адресная программа'!$O$20:$O$4940,'Адресная программа'!$L$20:$L$4940,1,'Адресная программа'!$C$20:$C$4940,АЗС!B31,'Адресная программа'!$G$20:$G$4940,АЗС!C31,'Адресная программа'!$F$20:$F$4940,"АЗС")) | E31: ='Цены|Скидки'!$F$11/15*$L$9 | F31: =E31*$L$7*D31 | G31: =IF(D31=SUMIFS('Адресная программа'!$K$20:$K$4940,'Адресная программа'!$L$20:$L$4940,1,'Адресная программа'!$C$20:$C$4940,АЗС!B31,'Адресная программа'!$G$20:$G$4940,"<>Газпромнефть",'Адресная программа'!$F$20:$F$4940,"АЗС"),'Цены|Скидки'!$C$31,IF(D31>=(SUMIFS('Адресная программа'!$K$20:$K$4940,'Адресная программа'!$L$20:$L$4940,1,'Адресная программа'!$C$20:$C$4940,АЗС!B31,'Адресная программа'!$G$20:$G$4940,"<>Газпромнефть",'Адресная программа'!$F$20:$F$4940,"АЗС")*'Цены|Скидки'!$B$32),'Цены|Скидки'!$C$32,IF(D31>=(SUMIFS('Адресная программа'!$K$20:$K$4940,'Адресная программа'!$L$20:$L$4940,1,'Адресная программа'!$C$20:$C$4940,АЗС!B31,'Адресная программа'!$G$20:$G$4940,"<>Газпромнефть",'Адресная программа'!$F$20:$F$4940,"АЗС")*'Цены|Скидки'!$B$33),'Цены|Скидки'!$C$33,IF(D31>=(SUMIFS('Адресная программа'!$K$20:$K$4940,'Адресная программа'!$L$20:$L$4940,1,'Адресная программа'!$C$20:$C$4940,АЗС!B31,'Адресная программа'!$G$20:$G$4940,"<>Газпромнефть",'Адресная программа'!$F$20:$F$4940,"АЗС")*'Цены|Скидки'!$B$34),'Цены|Скидки'!$C$34,0%)))) | H31: =D$12 | J31: =IF(D31=0,0,1-K31/F31) | K31: =F31*(1-G31)*(1-H31)*(1-IF($AC$2="РА",$AD$2,0))*(1-IF(OR($AC$3="Доп скидка",$AC$3="Сезонная скидка",$AC$3="Welcome скидка")=TRUE,$AD$3,0)) | L31: =K31+M31 | M31: =K31*0.2 | N31: =D31*L$7*1195 | O31: =IF(N31=0,0,(K31/N31*1000)/$D$7*10)
B32: Брянск | C32: Роснефть | D32: =IF(C32="АЗС",SUMIFS('Адресная программа'!$O$20:$O$4940,'Адресная программа'!$L$20:$L$4940,1,'Адресная программа'!$C$20:$C$4940,АЗС!B32,'Адресная программа'!$F$20:$F$4940,"АЗС",'Адресная программа'!$G$20:$G$4940,"<>Газпромнефть"),SUMIFS('Адресная программа'!$O$20:$O$4940,'Адресная программа'!$L$20:$L$4940,1,'Адресная программа'!$C$20:$C$4940,АЗС!B32,'Адресная программа'!$G$20:$G$4940,АЗС!C32,'Адресная программа'!$F$20:$F$4940,"АЗС")) | E32: ='Цены|Скидки'!$F$11/15*$L$9 | F32: =E32*$L$7*D32 | G32: =IF(D32=SUMIFS('Адресная программа'!$K$20:$K$4940,'Адресная программа'!$L$20:$L$4940,1,'Адресная программа'!$C$20:$C$4940,АЗС!B32,'Адресная программа'!$G$20:$G$4940,"<>Газпромнефть",'Адресная программа'!$F$20:$F$4940,"АЗС"),'Цены|Скидки'!$C$31,IF(D32>=(SUMIFS('Адресная программа'!$K$20:$K$4940,'Адресная программа'!$L$20:$L$4940,1,'Адресная программа'!$C$20:$C$4940,АЗС!B32,'Адресная программа'!$G$20:$G$4940,"<>Газпромнефть",'Адресная программа'!$F$20:$F$4940,"АЗС")*'Цены|Скидки'!$B$32),'Цены|Скидки'!$C$32,IF(D32>=(SUMIFS('Адресная программа'!$K$20:$K$4940,'Адресная программа'!$L$20:$L$4940,1,'Адресная программа'!$C$20:$C$4940,АЗС!B32,'Адресная программа'!$G$20:$G$4940,"<>Газпромнефть",'Адресная программа'!$F$20:$F$4940,"АЗС")*'Цены|Скидки'!$B$33),'Цены|Скидки'!$C$33,IF(D32>=(SUMIFS('Адресная программа'!$K$20:$K$4940,'Адресная программа'!$L$20:$L$4940,1,'Адресная программа'!$C$20:$C$4940,АЗС!B32,'Адресная программа'!$G$20:$G$4940,"<>Газпромнефть",'Адресная программа'!$F$20:$F$4940,"АЗС")*'Цены|Скидки'!$B$34),'Цены|Скидки'!$C$34,0%)))) | H32: =D$12 | J32: =IF(D32=0,0,1-K32/F32) | K32: =F32*(1-G32)*(1-H32)*(1-IF($AC$2="РА",$AD$2,0))*(1-IF(OR($AC$3="Доп скидка",$AC$3="Сезонная скидка",$AC$3="Welcome скидка")=TRUE,$AD$3,0)) | L32: =K32+M32 | M32: =K32*0.2 | N32: =D32*L$7*1015 | O32: =IF(N32=0,0,(K32/N32*1000)/$D$7*10)
B33: Владимир | C33: Роснефть | D33: =IF(C33="АЗС",SUMIFS('Адресная программа'!$O$20:$O$4940,'Адресная программа'!$L$20:$L$4940,1,'Адресная программа'!$C$20:$C$4940,АЗС!B33,'Адресная программа'!$F$20:$F$4940,"АЗС",'Адресная программа'!$G$20:$G$4940,"<>Газпромнефть"),SUMIFS('Адресная программа'!$O$20:$O$4940,'Адресная программа'!$L$20:$L$4940,1,'Адресная программа'!$C$20:$C$4940,АЗС!B33,'Адресная программа'!$G$20:$G$4940,АЗС!C33,'Адресная программа'!$F$20:$F$4940,"АЗС")) | E33: ='Цены|Скидки'!$F$11/15*$L$9 | F33: =E33*$L$7*D33 | G33: =IF(D33=SUMIFS('Адресная программа'!$K$20:$K$4940,'Адресная программа'!$L$20:$L$4940,1,'Адресная программа'!$C$20:$C$4940,АЗС!B33,'Адресная программа'!$G$20:$G$4940,"<>Газпромнефть",'Адресная программа'!$F$20:$F$4940,"АЗС"),'Цены|Скидки'!$C$31,IF(D33>=(SUMIFS('Адресная программа'!$K$20:$K$4940,'Адресная программа'!$L$20:$L$4940,1,'Адресная программа'!$C$20:$C$4940,АЗС!B33,'Адресная программа'!$G$20:$G$4940,"<>Газпромнефть",'Адресная программа'!$F$20:$F$4940,"АЗС")*'Цены|Скидки'!$B$32),'Цены|Скидки'!$C$32,IF(D33>=(SUMIFS('Адресная программа'!$K$20:$K$4940,'Адресная программа'!$L$20:$L$4940,1,'Адресная программа'!$C$20:$C$4940,АЗС!B33,'Адресная программа'!$G$20:$G$4940,"<>Газпромнефть",'Адресная программа'!$F$20:$F$4940,"АЗС")*'Цены|Скидки'!$B$33),'Цены|Скидки'!$C$33,IF(D33>=(SUMIFS('Адресная программа'!$K$20:$K$4940,'Адресная программа'!$L$20:$L$4940,1,'Адресная программа'!$C$20:$C$4940,АЗС!B33,'Адресная программа'!$G$20:$G$4940,"<>Газпромнефть",'Адресная программа'!$F$20:$F$4940,"АЗС")*'Цены|Скидки'!$B$34),'Цены|Скидки'!$C$34,0%)))) | H33: =D$12 | J33: =IF(D33=0,0,1-K33/F33) | K33: =F33*(1-G33)*(1-H33)*(1-IF($AC$2="РА",$AD$2,0))*(1-IF(OR($AC$3="Доп скидка",$AC$3="Сезонная скидка",$AC$3="Welcome скидка")=TRUE,$AD$3,0)) | L33: =K33+M33 | M33: =K33*0.2 | N33: =D33*L$7*1090 | O33: =IF(N33=0,0,(K33/N33*1000)/$D$7*10)
B34: ЦФО (Калуга, Тула, Тверь, Рязань,Смоленск,Владимир,Воронеж, Ярославль) | C34: Газпромнефть | D34: =IF(C34="АЗС",SUMIFS('Адресная программа'!$O$20:$O$4940,'Адресная программа'!$L$20:$L$4940,1,'Адресная программа'!$C$20:$C$4940,АЗС!B34,'Адресная программа'!$F$20:$F$4940,"АЗС",'Адресная программа'!$G$20:$G$4940,"<>Газпромнефть"),SUMIFS('Адресная программа'!$O$20:$O$4940,'Адресная программа'!$L$20:$L$4940,1,'Адресная программа'!$C$20:$C$4940,АЗС!B34,'Адресная программа'!$G$20:$G$4940,АЗС!C34,'Адресная программа'!$F$20:$F$4940,"АЗС")) | E34: ='Цены|Скидки'!$I$11/15*$L$9 | F34: =E34*$L$7*D34 | G34: =IF(D34=SUMIFS('Адресная программа'!$K$20:$K$4940,'Адресная программа'!$L$20:$L$4940,1,'Адресная программа'!$C$20:$C$4940,АЗС!B34,'Адресная программа'!$G$20:$G$4940,"=Газпромнефть",'Адресная программа'!$F$20:$F$4940,"АЗС"),'Цены|Скидки'!$C$43,IF(D34>=(SUMIFS('Адресная программа'!$K$20:$K$4940,'Адресная программа'!$L$20:$L$4940,1,'Адресная программа'!$C$20:$C$4940,АЗС!B34,'Адресная программа'!$G$20:$G$4940,"=Газпромнефть",'Адресная программа'!$F$20:$F$4940,"АЗС")*'Цены|Скидки'!$B$44),'Цены|Скидки'!$C$44,IF(D34>=(SUMIFS('Адресная программа'!$K$20:$K$4940,'Адресная программа'!$L$20:$L$4940,1,'Адресная программа'!$C$20:$C$4940,АЗС!B34,'Адресная программа'!$G$20:$G$4940,"=Газпромнефть",'Адресная программа'!$F$20:$F$4940,"АЗС")*'Цены|Скидки'!$B$45),'Цены|Скидки'!$C$45,IF(D34>=(SUMIFS('Адресная программа'!$K$20:$K$4940,'Адресная программа'!$L$20:$L$4940,1,'Адресная программа'!$C$20:$C$4940,АЗС!B34,'Адресная программа'!$G$20:$G$4940,"=Газпромнефть",'Адресная программа'!$F$20:$F$4940,"АЗС")*'Цены|Скидки'!$B$46),'Цены|Скидки'!$C$46,0%)))) | H34: =D$12 | I34: ='Адресная программа'!Y19 | J34: =IF(D34=0,0,1-K34/F34) | K34: =F34*(1-G34)*(1-H34)*(1-IF($AC$2="РА",$AD$2,0))*(1-IF(OR($AC$3="Доп скидка",$AC$3="Сезонная скидка",$AC$3="Welcome скидка")=TRUE,$AD$3,0))*(1-'Адресная программа'!Y19) | L34: =K34+M34 | M34: =K34*0.2 | N34: =D34*L$7*1090 | O34: =IF(N34=0,0,(K34/N34*1000)/$D$7*10)
B35: Владикавказ | C35: Лукойл | D35: =IF(C35="АЗС",SUMIFS('Адресная программа'!$O$20:$O$4940,'Адресная программа'!$L$20:$L$4940,1,'Адресная программа'!$C$20:$C$4940,АЗС!B35,'Адресная программа'!$F$20:$F$4940,"АЗС",'Адресная программа'!$G$20:$G$4940,"<>Газпромнефть"),SUMIFS('Адресная программа'!$O$20:$O$4940,'Адресная программа'!$L$20:$L$4940,1,'Адресная программа'!$C$20:$C$4940,АЗС!B35,'Адресная программа'!$G$20:$G$4940,АЗС!C35,'Адресная программа'!$F$20:$F$4940,"АЗС")) | E35: ='Цены|Скидки'!$F$11/15*$L$9 | F35: =E35*$L$7*D35 | G35: =IF(D35=SUMIFS('Адресная программа'!$K$20:$K$4940,'Адресная программа'!$L$20:$L$4940,1,'Адресная программа'!$C$20:$C$4940,АЗС!B35,'Адресная программа'!$G$20:$G$4940,"<>Газпромнефть",'Адресная программа'!$F$20:$F$4940,"АЗС"),'Цены|Скидки'!$C$31,IF(D35>=(SUMIFS('Адресная программа'!$K$20:$K$4940,'Адресная программа'!$L$20:$L$4940,1,'Адресная программа'!$C$20:$C$4940,АЗС!B35,'Адресная программа'!$G$20:$G$4940,"<>Газпромнефть",'Адресная программа'!$F$20:$F$4940,"АЗС")*'Цены|Скидки'!$B$32),'Цены|Скидки'!$C$32,IF(D35>=(SUMIFS('Адресная программа'!$K$20:$K$4940,'Адресная программа'!$L$20:$L$4940,1,'Адресная программа'!$C$20:$C$4940,АЗС!B35,'Адресная программа'!$G$20:$G$4940,"<>Газпромнефть",'Адресная программа'!$F$20:$F$4940,"АЗС")*'Цены|Скидки'!$B$33),'Цены|Скидки'!$C$33,IF(D35>=(SUMIFS('Адресная программа'!$K$20:$K$4940,'Адресная программа'!$L$20:$L$4940,1,'Адресная программа'!$C$20:$C$4940,АЗС!B35,'Адресная программа'!$G$20:$G$4940,"<>Газпромнефть",'Адресная программа'!$F$20:$F$4940,"АЗС")*'Цены|Скидки'!$B$34),'Цены|Скидки'!$C$34,0%)))) | H35: =D$12 | J35: =IF(D35=0,0,1-K35/F35) | K35: =F35*(1-G35)*(1-H35)*(1-IF($AC$2="РА",$AD$2,0))*(1-IF(OR($AC$3="Доп скидка",$AC$3="Сезонная скидка",$AC$3="Welcome скидка")=TRUE,$AD$3,0)) | L35: =K35+M35 | M35: =K35*0.2 | N35: =D35*$L$7*1045 | O35: =IF(N35=0,0,(K35/N35*1000)/$D$7*10)
B36: Волгоград | C36: Роснефть | D36: =IF(C36="АЗС",SUMIFS('Адресная программа'!$O$20:$O$4940,'Адресная программа'!$L$20:$L$4940,1,'Адресная программа'!$C$20:$C$4940,АЗС!B36,'Адресная программа'!$F$20:$F$4940,"АЗС",'Адресная программа'!$G$20:$G$4940,"<>Газпромнефть"),SUMIFS('Адресная программа'!$O$20:$O$4940,'Адресная программа'!$L$20:$L$4940,1,'Адресная программа'!$C$20:$C$4940,АЗС!B36,'Адресная программа'!$G$20:$G$4940,АЗС!C36,'Адресная программа'!$F$20:$F$4940,"АЗС")) | E36: ='Цены|Скидки'!$F$11/15*$L$9 | F36: =E36*$L$7*D36 | G36: =IF(D36=SUMIFS('Адресная программа'!$K$20:$K$4940,'Адресная программа'!$L$20:$L$4940,1,'Адресная программа'!$C$20:$C$4940,АЗС!B36,'Адресная программа'!$G$20:$G$4940,"<>Газпромнефть",'Адресная программа'!$F$20:$F$4940,"АЗС"),'Цены|Скидки'!$C$31,IF(D36>=(SUMIFS('Адресная программа'!$K$20:$K$4940,'Адресная программа'!$L$20:$L$4940,1,'Адресная программа'!$C$20:$C$4940,АЗС!B36,'Адресная программа'!$G$20:$G$4940,"<>Газпромнефть",'Адресная программа'!$F$20:$F$4940,"АЗС")*'Цены|Скидки'!$B$32),'Цены|Скидки'!$C$32,IF(D36>=(SUMIFS('Адресная программа'!$K$20:$K$4940,'Адресная программа'!$L$20:$L$4940,1,'Адресная программа'!$C$20:$C$4940,АЗС!B36,'Адресная программа'!$G$20:$G$4940,"<>Газпромнефть",'Адресная программа'!$F$20:$F$4940,"АЗС")*'Цены|Скидки'!$B$33),'Цены|Скидки'!$C$33,IF(D36>=(SUMIFS('Адресная программа'!$K$20:$K$4940,'Адресная программа'!$L$20:$L$4940,1,'Адресная программа'!$C$20:$C$4940,АЗС!B36,'Адресная программа'!$G$20:$G$4940,"<>Газпромнефть",'Адресная программа'!$F$20:$F$4940,"АЗС")*'Цены|Скидки'!$B$34),'Цены|Скидки'!$C$34,0%)))) | H36: =D$12 | J36: =IF(D36=0,0,1-K36/F36) | K36: =F36*(1-G36)*(1-H36)*(1-IF($AC$2="РА",$AD$2,0))*(1-IF(OR($AC$3="Доп скидка",$AC$3="Сезонная скидка",$AC$3="Welcome скидка")=TRUE,$AD$3,0)) | L36: =K36+M36 | M36: =K36*0.2 | N36: =D36*$L$7*1045 | O36: =IF(N36=0,0,(K36/N36*1000)/$D$7*10)
B37: Воронеж | C37: Роснефть | D37: =IF(C37="АЗС",SUMIFS('Адресная программа'!$O$20:$O$4940,'Адресная программа'!$L$20:$L$4940,1,'Адресная программа'!$C$20:$C$4940,АЗС!B37,'Адресная программа'!$F$20:$F$4940,"АЗС",'Адресная программа'!$G$20:$G$4940,"<>Газпромнефть"),SUMIFS('Адресная программа'!$O$20:$O$4940,'Адресная программа'!$L$20:$L$4940,1,'Адресная программа'!$C$20:$C$4940,АЗС!B37,'Адресная программа'!$G$20:$G$4940,АЗС!C37,'Адресная программа'!$F$20:$F$4940,"АЗС")) | E37: ='Цены|Скидки'!$F$11/15*$L$9 | F37: =E37*$L$7*D37 | G37: =IF(D37=SUMIFS('Адресная программа'!$K$20:$K$4940,'Адресная программа'!$L$20:$L$4940,1,'Адресная программа'!$C$20:$C$4940,АЗС!B37,'Адресная программа'!$G$20:$G$4940,"<>Газпромнефть",'Адресная программа'!$F$20:$F$4940,"АЗС"),'Цены|Скидки'!$C$31,IF(D37>=(SUMIFS('Адресная программа'!$K$20:$K$4940,'Адресная программа'!$L$20:$L$4940,1,'Адресная программа'!$C$20:$C$4940,АЗС!B37,'Адресная программа'!$G$20:$G$4940,"<>Газпромнефть",'Адресная программа'!$F$20:$F$4940,"АЗС")*'Цены|Скидки'!$B$32),'Цены|Скидки'!$C$32,IF(D37>=(SUMIFS('Адресная программа'!$K$20:$K$4940,'Адресная программа'!$L$20:$L$4940,1,'Адресная программа'!$C$20:$C$4940,АЗС!B37,'Адресная программа'!$G$20:$G$4940,"<>Газпромнефть",'Адресная программа'!$F$20:$F$4940,"АЗС")*'Цены|Скидки'!$B$33),'Цены|Скидки'!$C$33,IF(D37>=(SUMIFS('Адресная программа'!$K$20:$K$4940,'Адресная программа'!$L$20:$L$4940,1,'Адресная программа'!$C$20:$C$4940,АЗС!B37,'Адресная программа'!$G$20:$G$4940,"<>Газпромнефть",'Адресная программа'!$F$20:$F$4940,"АЗС")*'Цены|Скидки'!$B$34),'Цены|Скидки'!$C$34,0%)))) | H37: =D$12 | J37: =IF(D37=0,0,1-K37/F37) | K37: =F37*(1-G37)*(1-H37)*(1-IF($AC$2="РА",$AD$2,0))*(1-IF(OR($AC$3="Доп скидка",$AC$3="Сезонная скидка",$AC$3="Welcome скидка")=TRUE,$AD$3,0)) | L37: =K37+M37 | M37: =K37*0.2 | N37: =D37*L$7*1155 | O37: =IF(N37=0,0,(K37/N37*1000)/$D$7*10)
B38: Екатеринбург | C38: Башнефть | D38: =IF(C38="АЗС",SUMIFS('Адресная программа'!$O$20:$O$4940,'Адресная программа'!$L$20:$L$4940,1,'Адресная программа'!$C$20:$C$4940,АЗС!B38,'Адресная программа'!$F$20:$F$4940,"АЗС",'Адресная программа'!$G$20:$G$4940,"<>Газпромнефть"),SUMIFS('Адресная программа'!$O$20:$O$4940,'Адресная программа'!$L$20:$L$4940,1,'Адресная программа'!$C$20:$C$4940,АЗС!B38,'Адресная программа'!$G$20:$G$4940,АЗС!C38,'Адресная программа'!$F$20:$F$4940,"АЗС")) | E38: ='Цены|Скидки'!$F$11/15*$L$9 | F38: =E38*$L$7*D38 | G38: =IF(D38=SUMIFS('Адресная программа'!$K$20:$K$4940,'Адресная программа'!$L$20:$L$4940,1,'Адресная программа'!$C$20:$C$4940,АЗС!B38,'Адресная программа'!$G$20:$G$4940,"<>Газпромнефть",'Адресная программа'!$F$20:$F$4940,"АЗС"),'Цены|Скидки'!$C$31,IF(D38>=(SUMIFS('Адресная программа'!$K$20:$K$4940,'Адресная программа'!$L$20:$L$4940,1,'Адресная программа'!$C$20:$C$4940,АЗС!B38,'Адресная программа'!$G$20:$G$4940,"<>Газпромнефть",'Адресная программа'!$F$20:$F$4940,"АЗС")*'Цены|Скидки'!$B$32),'Цены|Скидки'!$C$32,IF(D38>=(SUMIFS('Адресная программа'!$K$20:$K$4940,'Адресная программа'!$L$20:$L$4940,1,'Адресная программа'!$C$20:$C$4940,АЗС!B38,'Адресная программа'!$G$20:$G$4940,"<>Газпромнефть",'Адресная программа'!$F$20:$F$4940,"АЗС")*'Цены|Скидки'!$B$33),'Цены|Скидки'!$C$33,IF(D38>=(SUMIFS('Адресная программа'!$K$20:$K$4940,'Адресная программа'!$L$20:$L$4940,1,'Адресная программа'!$C$20:$C$4940,АЗС!B38,'Адресная программа'!$G$20:$G$4940,"<>Газпромнефть",'Адресная программа'!$F$20:$F$4940,"АЗС")*'Цены|Скидки'!$B$34),'Цены|Скидки'!$C$34,0%)))) | H38: =D$12 | J38: =IF(D38=0,0,1-K38/F38) | K38: =F38*(1-G38)*(1-H38)*(1-IF($AC$2="РА",$AD$2,0))*(1-IF(OR($AC$3="Доп скидка",$AC$3="Сезонная скидка",$AC$3="Welcome скидка")=TRUE,$AD$3,0)) | L38: =K38+M38 | M38: =K38*0.2 | N38: =D38*L$7*1260 | O38: =IF(N38=0,0,(K38/N38*1000)/$D$7*10)
B39: Екатеринбург | C39: Газпромнефть | D39: =IF(C39="АЗС",SUMIFS('Адресная программа'!$O$20:$O$4940,'Адресная программа'!$L$20:$L$4940,1,'Адресная программа'!$C$20:$C$4940,АЗС!B39,'Адресная программа'!$F$20:$F$4940,"АЗС",'Адресная программа'!$G$20:$G$4940,"<>Газпромнефть"),SUMIFS('Адресная программа'!$O$20:$O$4940,'Адресная программа'!$L$20:$L$4940,1,'Адресная программа'!$C$20:$C$4940,АЗС!B39,'Адресная программа'!$G$20:$G$4940,АЗС!C39,'Адресная программа'!$F$20:$F$4940,"АЗС")) | E39: ='Цены|Скидки'!$I$11/15*$L$9 | F39: =E39*$L$7*D39 | G39: =IF(D39=SUMIFS('Адресная программа'!$K$20:$K$4940,'Адресная программа'!$L$20:$L$4940,1,'Адресная программа'!$C$20:$C$4940,АЗС!B39,'Адресная программа'!$G$20:$G$4940,"=Газпромнефть",'Адресная программа'!$F$20:$F$4940,"АЗС"),'Цены|Скидки'!$C$43,IF(D39>=(SUMIFS('Адресная программа'!$K$20:$K$4940,'Адресная программа'!$L$20:$L$4940,1,'Адресная программа'!$C$20:$C$4940,АЗС!B39,'Адресная программа'!$G$20:$G$4940,"=Газпромнефть",'Адресная программа'!$F$20:$F$4940,"АЗС")*'Цены|Скидки'!$B$44),'Цены|Скидки'!$C$44,IF(D39>=(SUMIFS('Адресная программа'!$K$20:$K$4940,'Адресная программа'!$L$20:$L$4940,1,'Адресная программа'!$C$20:$C$4940,АЗС!B39,'Адресная программа'!$G$20:$G$4940,"=Газпромнефть",'Адресная программа'!$F$20:$F$4940,"АЗС")*'Цены|Скидки'!$B$45),'Цены|Скидки'!$C$45,IF(D39>=(SUMIFS('Адресная программа'!$K$20:$K$4940,'Адресная программа'!$L$20:$L$4940,1,'Адресная программа'!$C$20:$C$4940,АЗС!B39,'Адресная программа'!$G$20:$G$4940,"=Газпромнефть",'Адресная программа'!$F$20:$F$4940,"АЗС")*'Цены|Скидки'!$B$46),'Цены|Скидки'!$C$46,0%)))) | H39: =$D$12 | I39: ='Адресная программа'!Y19 | J39: =IF(D39=0,0,1-K39/F39) | K39: =F39*(1-G39)*(1-H39)*(1-IF($AC$2="РА",$AD$2,0))*(1-IF(OR($AC$3="Доп скидка",$AC$3="Сезонная скидка",$AC$3="Welcome скидка")=TRUE,$AD$3,0))*(1-'Адресная программа'!Y19) | L39: =K39+M39 | M39: =K39*0.2 | N39: =D39*$L$7*1210 | O39: =IF(N39=0,0,(K39/N39*1000)/$D$7*10)
B40: Ижевск | C40: Башнефть | D40: =IF(C40="АЗС",SUMIFS('Адресная программа'!$O$20:$O$4940,'Адресная программа'!$L$20:$L$4940,1,'Адресная программа'!$C$20:$C$4940,АЗС!B40,'Адресная программа'!$F$20:$F$4940,"АЗС",'Адресная программа'!$G$20:$G$4940,"<>Газпромнефть"),SUMIFS('Адресная программа'!$O$20:$O$4940,'Адресная программа'!$L$20:$L$4940,1,'Адресная программа'!$C$20:$C$4940,АЗС!B40,'Адресная программа'!$G$20:$G$4940,АЗС!C40,'Адресная программа'!$F$20:$F$4940,"АЗС")) | E40: ='Цены|Скидки'!$F$11/15*$L$9 | F40: =E40*$L$7*D40 | G40: =IF(D40=SUMIFS('Адресная программа'!$K$20:$K$4940,'Адресная программа'!$L$20:$L$4940,1,'Адресная программа'!$C$20:$C$4940,АЗС!B40,'Адресная программа'!$G$20:$G$4940,"<>Газпромнефть",'Адресная программа'!$F$20:$F$4940,"АЗС"),'Цены|Скидки'!$C$31,IF(D40>=(SUMIFS('Адресная программа'!$K$20:$K$4940,'Адресная программа'!$L$20:$L$4940,1,'Адресная программа'!$C$20:$C$4940,АЗС!B40,'Адресная программа'!$G$20:$G$4940,"<>Газпромнефть",'Адресная программа'!$F$20:$F$4940,"АЗС")*'Цены|Скидки'!$B$32),'Цены|Скидки'!$C$32,IF(D40>=(SUMIFS('Адресная программа'!$K$20:$K$4940,'Адресная программа'!$L$20:$L$4940,1,'Адресная программа'!$C$20:$C$4940,АЗС!B40,'Адресная программа'!$G$20:$G$4940,"<>Газпромнефть",'Адресная программа'!$F$20:$F$4940,"АЗС")*'Цены|Скидки'!$B$33),'Цены|Скидки'!$C$33,IF(D40>=(SUMIFS('Адресная программа'!$K$20:$K$4940,'Адресная программа'!$L$20:$L$4940,1,'Адресная программа'!$C$20:$C$4940,АЗС!B40,'Адресная программа'!$G$20:$G$4940,"<>Газпромнефть",'Адресная программа'!$F$20:$F$4940,"АЗС")*'Цены|Скидки'!$B$34),'Цены|Скидки'!$C$34,0%)))) | H40: =D$12 | J40: =IF(D40=0,0,1-K40/F40) | K40: =F40*(1-G40)*(1-H40)*(1-IF($AC$2="РА",$AD$2,0))*(1-IF(OR($AC$3="Доп скидка",$AC$3="Сезонная скидка",$AC$3="Welcome скидка")=TRUE,$AD$3,0)) | L40: =K40+M40 | M40: =K40*0.2 | N40: =D40*L$7*1085 | O40: =IF(N40=0,0,(K40/N40*1000)/$D$7*10)
B41: Иркутск | C41: Роснефть | D41: =IF(C41="АЗС",SUMIFS('Адресная программа'!$O$20:$O$4940,'Адресная программа'!$L$20:$L$4940,1,'Адресная программа'!$C$20:$C$4940,АЗС!B41,'Адресная программа'!$F$20:$F$4940,"АЗС",'Адресная программа'!$G$20:$G$4940,"<>Газпромнефть"),SUMIFS('Адресная программа'!$O$20:$O$4940,'Адресная программа'!$L$20:$L$4940,1,'Адресная программа'!$C$20:$C$4940,АЗС!B41,'Адресная программа'!$G$20:$G$4940,АЗС!C41,'Адресная программа'!$F$20:$F$4940,"АЗС")) | E41: ='Цены|Скидки'!$F$11/15*$L$9 | F41: =E41*$L$7*D41 | G41: =IF(D41=SUMIFS('Адресная программа'!$K$20:$K$4940,'Адресная программа'!$L$20:$L$4940,1,'Адресная программа'!$C$20:$C$4940,АЗС!B41,'Адресная программа'!$G$20:$G$4940,"<>Газпромнефть",'Адресная программа'!$F$20:$F$4940,"АЗС"),'Цены|Скидки'!$C$31,IF(D41>=(SUMIFS('Адресная программа'!$K$20:$K$4940,'Адресная программа'!$L$20:$L$4940,1,'Адресная программа'!$C$20:$C$4940,АЗС!B41,'Адресная программа'!$G$20:$G$4940,"<>Газпромнефть",'Адресная программа'!$F$20:$F$4940,"АЗС")*'Цены|Скидки'!$B$32),'Цены|Скидки'!$C$32,IF(D41>=(SUMIFS('Адресная программа'!$K$20:$K$4940,'Адресная программа'!$L$20:$L$4940,1,'Адресная программа'!$C$20:$C$4940,АЗС!B41,'Адресная программа'!$G$20:$G$4940,"<>Газпромнефть",'Адресная программа'!$F$20:$F$4940,"АЗС")*'Цены|Скидки'!$B$33),'Цены|Скидки'!$C$33,IF(D41>=(SUMIFS('Адресная программа'!$K$20:$K$4940,'Адресная программа'!$L$20:$L$4940,1,'Адресная программа'!$C$20:$C$4940,АЗС!B41,'Адресная программа'!$G$20:$G$4940,"<>Газпромнефть",'Адресная программа'!$F$20:$F$4940,"АЗС")*'Цены|Скидки'!$B$34),'Цены|Скидки'!$C$34,0%)))) | H41: =D$12 | J41: =IF(D41=0,0,1-K41/F41) | K41: =F41*(1-G41)*(1-H41)*(1-IF($AC$2="РА",$AD$2,0))*(1-IF(OR($AC$3="Доп скидка",$AC$3="Сезонная скидка",$AC$3="Welcome скидка")=TRUE,$AD$3,0)) | L41: =K41+M41 | M41: =K41*0.2 | N41: =D41*L$7*1085 | O41: =IF(N41=0,0,(K41/N41*1000)/$D$7*10)
B42: Калуга | C42: Роснефть | D42: =IF(C42="АЗС",SUMIFS('Адресная программа'!$O$20:$O$4940,'Адресная программа'!$L$20:$L$4940,1,'Адресная программа'!$C$20:$C$4940,АЗС!B42,'Адресная программа'!$F$20:$F$4940,"АЗС",'Адресная программа'!$G$20:$G$4940,"<>Газпромнефть"),SUMIFS('Адресная программа'!$O$20:$O$4940,'Адресная программа'!$L$20:$L$4940,1,'Адресная программа'!$C$20:$C$4940,АЗС!B42,'Адресная программа'!$G$20:$G$4940,АЗС!C42,'Адресная программа'!$F$20:$F$4940,"АЗС")) | E42: ='Цены|Скидки'!$F$11/15*$L$9 | F42: =E42*$L$7*D42 | G42: =IF(D42=SUMIFS('Адресная программа'!$K$20:$K$4940,'Адресная программа'!$L$20:$L$4940,1,'Адресная программа'!$C$20:$C$4940,АЗС!B42,'Адресная программа'!$G$20:$G$4940,"<>Газпромнефть",'Адресная программа'!$F$20:$F$4940,"АЗС"),'Цены|Скидки'!$C$31,IF(D42>=(SUMIFS('Адресная программа'!$K$20:$K$4940,'Адресная программа'!$L$20:$L$4940,1,'Адресная программа'!$C$20:$C$4940,АЗС!B42,'Адресная программа'!$G$20:$G$4940,"<>Газпромнефть",'Адресная программа'!$F$20:$F$4940,"АЗС")*'Цены|Скидки'!$B$32),'Цены|Скидки'!$C$32,IF(D42>=(SUMIFS('Адресная программа'!$K$20:$K$4940,'Адресная программа'!$L$20:$L$4940,1,'Адресная программа'!$C$20:$C$4940,АЗС!B42,'Адресная программа'!$G$20:$G$4940,"<>Газпромнефть",'Адресная программа'!$F$20:$F$4940,"АЗС")*'Цены|Скидки'!$B$33),'Цены|Скидки'!$C$33,IF(D42>=(SUMIFS('Адресная программа'!$K$20:$K$4940,'Адресная программа'!$L$20:$L$4940,1,'Адресная программа'!$C$20:$C$4940,АЗС!B42,'Адресная программа'!$G$20:$G$4940,"<>Газпромнефть",'Адресная программа'!$F$20:$F$4940,"АЗС")*'Цены|Скидки'!$B$34),'Цены|Скидки'!$C$34,0%)))) | H42: =D$12 | J42: =IF(D42=0,0,1-K42/F42) | K42: =F42*(1-G42)*(1-H42)*(1-IF($AC$2="РА",$AD$2,0))*(1-IF(OR($AC$3="Доп скидка",$AC$3="Сезонная скидка",$AC$3="Welcome скидка")=TRUE,$AD$3,0)) | L42: =K42+M42 | M42: =K42*0.2 | N42: =D42*L$7*1085 | O42: =IF(N42=0,0,(K42/N42*1000)/$D$7*10)
...

Sheet Азбука вкуса
AN1: ПК | AO1: 0
B2: Супермаркеты «Азбука вкуса» | AC2: РА | AD2: 0.1 | AN2: РА | AO2: 0.05 | AP2: Доп скидка
B3: Клиент: | D3: Sminex | I3: Всего экранов: | K3: =D26 | AO3: 0.1 | AP3: Welcome скидка
B4: Бренд: | D4: Sminex | I4: Часов работы одного экрана в сутки: | K4: 24 | AO4: 0.15 | AP4: Сезонная скидка
B5: Начало РК: | D5: 45748 | I5: Продолжительность блока в минутах: | K5: 3 | AO5: 0.2
B6: Окончание РК: | D6: 45838 | I6: Блоков в сутки на одном экране: | K6: =K4*60/K5 | AO6: 0.25
B7: Ролик1, сек: | D7: 15 | I7: Кол-во дней размещения: | K7: =D6-D5+1
I8: Кол-во роликов в блоке: | K8: =COUNT(D$7,D$8,D$9)
B9: КАРТА ОХВАТА | D9: фото Азбука вкуса | I9: Итого секунд в блоке: | K9: =SUM(D7:D9) | AO9: 0
B10: Применяемые скидки (последовательно) | I10: Показов в день на одном экране: | K10: =K6*K8 | AO10: 0.05
B11: За кол-во экранов(средн): | D11: =SUBTOTAL(1,G22:G25) | I11: Минут в день на одном экране: | K11: =K6*K9/60 | AO11: 0.1
B12: За период: | D12: =IF(K7>69,'Цены|Скидки'!$C$100,IF(K7>39,'Цены|Скидки'!$C$99,0%)) | I12: Показов на всех экранах за период: | K12: =K10*K7*K3 | AO12: 0.15
B13: =IF(AC2="РА","Скидка для РА:"," ") | D13: =IF(AC2="РА",AD2," ") | I13: OTS: | K13: =M26 | AO13: 0.2
B14: =IF(AC3=0," ",AC3) | D14: =IF(OR(AC3="Доп скидка",AC3="Сезонная скидка",AC3="Welcome скидка")=TRUE,AD3," ") | I14: CPT: | K14: =N26 | AO14: 0.25
B15: Стоимость размещения
B16: Всего, руб. NET: | D16: =J26 | I16: Предоставление ролика до: | K16: =D5-3 | AW16: 16
B17: Всего, руб. GROSS: | D17: =K26 | I17: Оплата до: | K17: =D5-5 | AN17: Автобренд | AW17: 1
AW18: 17
B19: Расчет стоимости кампании в «Азбука вкуса»
B20: Регион | C20: Сеть | D20: Количество экранов | E20: Стоимость размещения в сутки на 1 экране, без НДС | F20: Стоимость размещения по выбранной АП за период, без НДС | G20: Скидка за кол-во экранов | H20: Скидка за период | I20: Итоговая скидка | J20: Стоимость c учетом всех скидок, без НДС | K20: Стоимость c учетом всех скидок, вкл. НДС | L20: Сумма НДС (20%) | M20: OTS | N20: CPT
B22: Москва | C22: Азбука Вкуса | D22: =SUMIFS('Адресная программа'!$O$388:$O$4169,'Адресная программа'!$C$388:$C$4169,'Азбука вкуса'!B22,'Адресная программа'!$G$388:$G$4169,'Азбука вкуса'!C22) | E22: =F22/$K$7/D22 | F22: =SUMIFS('Адресная программа'!$T$20:$T$4940,'Адресная программа'!$C$20:$C$4940,'Азбука вкуса'!B22,'Адресная программа'!$G$20:$G$4940,'Азбука вкуса'!C22,'Адресная программа'!$N$20:$N$4940,1)*$K$7*60/$K$5*$K$9*'Цены|Скидки'!D11/15/480 | G22: =IF(D22=SUMIFS('Адресная программа'!$K$20:$K$4940,'Адресная программа'!$G$20:$G$4940,'Азбука вкуса'!C22,'Адресная программа'!$C$20:$C$4940,'Азбука вкуса'!B22,'Адресная программа'!$L$20:$L$4940,1),'Цены|Скидки'!$C$31,IF(D22>(SUMIFS('Адресная программа'!$K$20:$K$4940,'Адресная программа'!$G$20:$G$4940,'Азбука вкуса'!C22,'Адресная программа'!$C$20:$C$4940,'Азбука вкуса'!B22,'Адресная программа'!$L$20:$L$4940,1)*'Цены|Скидки'!$B$32-1),'Цены|Скидки'!$C$32,IF(D22>(SUMIFS('Адресная программа'!$K$20:$K$4940,'Адресная программа'!$G$20:$G$4940,'Азбука вкуса'!C22,'Адресная программа'!$C$20:$C$4940,'Азбука вкуса'!B22,'Адресная программа'!$L$20:$L$4940,1)*'Цены|Скидки'!$B$33-1),'Цены|Скидки'!$C$33,IF(D22>(SUMIFS('Адресная программа'!$K$20:$K$4940,'Адресная программа'!$G$20:$G$4940,'Азбука вкуса'!C22,'Адресная программа'!$C$20:$C$4940,'Азбука вкуса'!B22,'Адресная программа'!$L$20:$L$4940,1)*'Цены|Скидки'!$B$34-1),'Цены|Скидки'!$C$34,IF(D22>(SUMIFS('Адресная программа'!$K$20:$K$4940,'Адресная программа'!$G$20:$G$4940,'Азбука вкуса'!C22,'Адресная программа'!$C$20:$C$4940,'Азбука вкуса'!B22,'Адресная программа'!$L$20:$L$4940,1)*'Цены|Скидки'!$B$35-1),'Цены|Скидки'!$C$35,IF(D22>(SUMIFS('Адресная программа'!$K$20:$K$4940,'Адресная программа'!$G$20:$G$4940,'Азбука вкуса'!C22,'Адресная программа'!$C$20:$C$4940,'Азбука вкуса'!B22,'Адресная программа'!$L$20:$L$4940,1)*'Цены|Скидки'!$B$36-1),'Цены|Скидки'!$C$36,0%)))))) | H22: =$D$12 | I22: =IF(F22=0,0,1-J22/F22) | J22: =F22*(1-G22)*(1-H22)*(1-IF(AC$2="РА",AD$2,0))*(1-IF(OR(AC$3="Доп скидка",AC$3="Сезонная скидка",AC$3="Welcome скидка")=TRUE,AD$3,0)) | K22: =J22+L22 | L22: =J22*0.2 | M22: =D22*K$7*1000 | N22: =J22/M22*1000
B23: Москва | C23: Энотека АВ | D23: =SUMIFS('Адресная программа'!$O$388:$O$4169,'Адресная программа'!$C$388:$C$4169,'Азбука вкуса'!B23,'Адресная программа'!$G$388:$G$4169,'Азбука вкуса'!C23) | E23: =F23/$K$7/D23 | F23: =SUMIFS('Адресная программа'!$T$20:$T$4940,'Адресная программа'!$C$20:$C$4940,'Азбука вкуса'!B23,'Адресная программа'!$G$20:$G$4940,'Азбука вкуса'!C23,'Адресная программа'!$N$20:$N$4940,1)*$K$7*60/$K$5*$K$9*'Цены|Скидки'!D11/15/480 | G23: =IF(D23=SUMIFS('Адресная программа'!$K$20:$K$4940,'Адресная программа'!$G$20:$G$4940,'Азбука вкуса'!C23,'Адресная программа'!$C$20:$C$4940,'Азбука вкуса'!B23,'Адресная программа'!$L$20:$L$4940,1),'Цены|Скидки'!$C$31,IF(D23>(SUMIFS('Адресная программа'!$K$20:$K$4940,'Адресная программа'!$G$20:$G$4940,'Азбука вкуса'!C23,'Адресная программа'!$C$20:$C$4940,'Азбука вкуса'!B23,'Адресная программа'!$L$20:$L$4940,1)*'Цены|Скидки'!$B$32-1),'Цены|Скидки'!$C$32,IF(D23>(SUMIFS('Адресная программа'!$K$20:$K$4940,'Адресная программа'!$G$20:$G$4940,'Азбука вкуса'!C23,'Адресная программа'!$C$20:$C$4940,'Азбука вкуса'!B23,'Адресная программа'!$L$20:$L$4940,1)*'Цены|Скидки'!$B$33-1),'Цены|Скидки'!$C$33,IF(D23>(SUMIFS('Адресная программа'!$K$20:$K$4940,'Адресная программа'!$G$20:$G$4940,'Азбука вкуса'!C23,'Адресная программа'!$C$20:$C$4940,'Азбука вкуса'!B23,'Адресная программа'!$L$20:$L$4940,1)*'Цены|Скидки'!$B$34-1),'Цены|Скидки'!$C$34,IF(D23>(SUMIFS('Адресная программа'!$K$20:$K$4940,'Адресная программа'!$G$20:$G$4940,'Азбука вкуса'!C23,'Адресная программа'!$C$20:$C$4940,'Азбука вкуса'!B23,'Адресная программа'!$L$20:$L$4940,1)*'Цены|Скидки'!$B$35-1),'Цены|Скидки'!$C$35,IF(D23>(SUMIFS('Адресная программа'!$K$20:$K$4940,'Адресная программа'!$G$20:$G$4940,'Азбука вкуса'!C23,'Адресная программа'!$C$20:$C$4940,'Азбука вкуса'!B23,'Адресная программа'!$L$20:$L$4940,1)*'Цены|Скидки'!$B$36-1),'Цены|Скидки'!$C$36,0%)))))) | H23: =$D$12 | I23: =IF(F23=0,0,1-J23/F23) | J23: =F23*(1-G23)*(1-H23)*(1-IF(AC$2="РА",AD$2,0))*(1-IF(OR(AC$3="Доп скидка",AC$3="Сезонная скидка",AC$3="Welcome скидка")=TRUE,AD$3,0)) | K23: =J23+L23 | L23: =J23*0.2 | M23: =D23*K$7*1000 | N23: =J23/M23*1000
B24: Санкт-Петербург | C24: Азбука Вкуса | D24: =SUMIFS('Адресная программа'!$O$388:$O$4169,'Адресная программа'!$C$388:$C$4169,'Азбука вкуса'!B24,'Адресная программа'!$G$388:$G$4169,'Азбука вкуса'!C24) | E24: =F24/$K$7/D24 | F24: =SUMIFS('Адресная программа'!$T$20:$T$4940,'Адресная программа'!$C$20:$C$4940,'Азбука вкуса'!B24,'Адресная программа'!$G$20:$G$4940,'Азбука вкуса'!C24,'Адресная программа'!$N$20:$N$4940,1)*$K$7*60/$K$5*$K$9*'Цены|Скидки'!E11/15/480 | I24: =IF(F24=0,0,1-J24/F24) | J24: =F24*(1-G24)*(1-H24)*(1-IF(AC$2="РА",AD$2,0))*(1-IF(OR(AC$3="Доп скидка",AC$3="Сезонная скидка",AC$3="Welcome скидка")=TRUE,AD$3,0)) | K24: =J24+L24 | L24: =J24*0.2 | M24: =D24*K$7*1000 | N24: =J24/M24*1000
B25: Санкт-Петербург | C25: Энотека АВ | D25: =SUMIFS('Адресная программа'!$O$388:$O$4169,'Адресная программа'!$C$388:$C$4169,'Азбука вкуса'!B25,'Адресная программа'!$G$388:$G$4169,'Азбука вкуса'!C25) | E25: =F25/$K$7/D25 | F25: =SUMIFS('Адресная программа'!$T$20:$T$4940,'Адресная программа'!$C$20:$C$4940,'Азбука вкуса'!B25,'Адресная программа'!$G$20:$G$4940,'Азбука вкуса'!C25,'Адресная программа'!$N$20:$N$4940,1)*$K$7*60/$K$5*$K$9*'Цены|Скидки'!E11/15/480 | I25: =IF(F25=0,0,1-J25/F25) | J25: =F25*(1-G25)*(1-H25)*(1-IF(AC$2="РА",AD$2,0))*(1-IF(OR(AC$3="Доп скидка",AC$3="Сезонная скидка",AC$3="Welcome скидка")=TRUE,AD$3,0)) | K25: =J25+L25 | L25: =J25*0.2 | M25: =D25*K$7*1000 | N25: =J25/M25*1000
D26: =SUM(D22:D25) | F26: =SUM(F22:F25) | J26: =SUM(J22:J25) | K26: =SUM(K22:K25) | L26: =SUM(L22:L25) | M26: =SUM(M22:M25) | N26: =J26/M26*1000

Sheet MetroCC
B2: Торговые центры Metro C&C | AB2: НЕ Поставщик | AD2: 0.15 | AI2: ПК | AJ2: 0 | AK2: НЕ Поставщик | AM2: Применяемые скидки (последовательно)
B3: Клиент: | G3: Всего ТЦ: | I3: =C40 | AD3: 0 | AI3: РА | AJ3: 0.05 | AK3: Поставщик | AL3: Доп скидка | AM3: За кол-во экранов(средн): | AO3: =IF(SUM($C$22:$C$38)=SUMIFS('Адресная программа'!$L$20:$L$4931,'Адресная программа'!$G$20:$G$4931,"Metro C&C",'Адресная программа'!$L$20:$L$4931,1),'Цены|Скидки'!C93,IF(SUM($C$22:$C$38)>(SUMIFS('Адресная программа'!$L$20:$L$4931,'Адресная программа'!$G$20:$G$4931,"Metro C&C",'Адресная программа'!$L$20:$L$4931,1)*'Цены|Скидки'!B94-1),'Цены|Скидки'!C94,IF(SUM($C$22:$C$38)>(SUMIFS('Адресная программа'!$L$20:$L$4931,'Адресная программа'!$G$20:$G$4931,"Metro C&C",'Адресная программа'!$L$20:$L$4931,1)*'Цены|Скидки'!B95-1),'Цены|Скидки'!C95,IF(SUM($C$22:$C$38)>(SUMIFS('Адресная программа'!$L$20:$L$4931,'Адресная программа'!$G$20:$G$4931,"Metro C&C",'Адресная программа'!$L$20:$L$4931,1)*'Цены|Скидки'!B96-1),'Цены|Скидки'!C96,0))))
B4: Бренд: | G4: Всего экранов: | I4: =D40 | AJ4: 0.1 | AL4: Welcome скидка | AM4: За период: | AO4: =IF(I7>69,'Цены|Скидки'!$C$100,IF(I7>39,'Цены|Скидки'!$C$99,0%))
B5: Начало РК: | D5: =Общий!D5 | G5: Продолжительность блока в минутах: | I5: 3 | AJ5: 0.15 | AL5: Сезонная скидка | AM5: Итоговая скидка: | AO5: =IF(SUM($C$22:$C$38)=0,0,1-SUM($G$22:$G$38)/SUM($F$22:$F$38))
B6: Окончание РК: | D6: =Общий!D6 | G6: Блоков в сутки на одном экране: | I6: =17*60/I5 | AJ6: 0.2
B7: Ролик1, сек: | D7: =Общий!D7 | G7: Кол-во дней размещения: | I7: =D6-D5+1 | AJ7: 0.25
B8: Ролик2, сек: | G8: Кол-во роликов в блоке: | I8: =COUNT(D$7,D$8)
B9: =IF(AB2=AK2,AM2,IF(AC2=AI3,AM2,"")) | G9: Итого секунд в блоке: | I9: =SUM(D7:D8) | AJ9: 0
B10: =IF(AB2=AK2,AM3,"") | D10: =IF(AB2=AK2,AO3,"") | G10: Показов в день на одном экране: | I10: =I6*I8 | AJ10: 0.05
B11: =IF(AB2=AK2,AM4,"") | D11: =IF(AB2=AK2,AO4,"") | G11: Минут в день на одном экране: | I11: =I6*I9/60 | AJ11: 0.1
B12: =IF(AC2="РА","Скидка для РА:"," ") | D12: =IF(AC2="РА",AD2," ") | AJ12: 0.15
B13: =IF(AC3=0," ",AC3) | D13: =IF(OR(AC3="Доп скидка",AC3="Сезонная скидка",AC3="Welcome скидка")=TRUE,AD3," ") | H13: OTS: | I13: =J40 | AJ13: 0.2
B14: =IF(AB2=AK2,AM5,IF(AC2=AI3,AM5,"")) | D14: =IF(AB2=AK2,AO5,IF(AC2=AI3,AO5,"")) | G14: Показов на всех экранах за период: | I14: =I10*I7*I4 | AJ14: 0.25
B15: Стоимость размещения
B16: Всего, руб. NET: | D16: =G40 | G16: Предоставление ролика до: | I16: =D5-3
B17: Всего, руб. GROSS: | D17: =H40 | G17: Оплата до: | I17: =D5-5
AI18: Автобренд
B19: Расчет стоимости кампании
B21: Регион | C21: Количество магазинов | D21: Количество экранов | E21: Стоимость размещения в сутки в одном ТЦ, без НДС | F21: Стоимость размещения по выбранной АП за период, без НДС | G21: Стоимость c учетом всех скидок, без НДС | H21: Стоимость c учетом всех скидок, вкл. НДС | I21: Сумма НДС (20%) | J21: OTS | K21: CPT*
B22: Москва | C22: =COUNTIFS('Адресная программа'!$V$20:$V$4169,B22,'Адресная программа'!$G$20:$G$4169,"Metro C&C") | D22: =SUMIFS('Адресная программа'!$O$20:$O$4169,'Адресная программа'!$V$20:$V$4169,B22,'Адресная программа'!$G$20:$G$4169,"Metro C&C") | E22: =IF(C22=0,0,AVERAGEIFS('Адресная программа'!$T$20:$T$4169,'Адресная программа'!$V$20:$V$4169,B22,'Адресная программа'!$G$20:$G$4169,"Metro C&C"))/15*$I$9 | F22: =E22*$I$7*C22 | G22: =IF($D$10="",IF($AC$2="РА",F22*(1-$AD$2),F22),F22*(1-$AO$3)*(1-$AO$4)*(1-IF($AC$2="РА",$AD$2,0))*(1-IF(OR($AC$3="Доп скидка",$AC$3="Сезонная скидка",$AC$3="Welcome скидка")=TRUE,$AD$3,0))) | H22: =G22+I22 | I22: =G22*0.2 | J22: =SUMIFS('Адресная программа'!$U$3366:$U$4209,'Адресная программа'!$V$3366:$V$4209,B22,'Адресная программа'!$G$3366:$G$4209,"Metro C&C")/30*$I$7 | K22: =IF(J22=0,0,(G22/J22*1000)/$D$7*10)
