Workbook
Name ПРАЙСБ: _xlfn.LAMBDA(IFERROR( IF(МП!$ES1="LisChannel", (ROUND(((INDEX({174.625;153.888888888889;130.972222222222},MATCH(МП!$AI1,{2;3;4}),0))*МП!$AG1*МП!$AI1),2)),0),0))

Sheet СВОД
B1: КЛИЕНТ | H1: БАИНГ | N1: ПОДТВЕРЖДЕНО БАИНГ
B2: =SUBTOTAL(9,B4:B18) -> 0 | C2: =SUBTOTAL(9,C4:C18) -> 0 | D2: =SUBTOTAL(9,D4:D18) -> 0 | E2: =SUBTOTAL(9,E4:E18) -> 0 | F2: =SUBTOTAL(9,F4:F18) -> 0 | H2: =SUBTOTAL(9,H4:H18) -> 0 | I2: =SUBTOTAL(9,I4:I18) -> 0 | J2: =SUBTOTAL(9,J4:J18) -> 0 | K2: =SUBTOTAL(9,K4:K18) -> 0 | L2: =SUBTOTAL(9,L4:L18) -> 0 | N2: =SUBTOTAL(9,N4:N18) -> 0 | O2: =SUBTOTAL(9,O4:O18) -> 0 | P2: =SUBTOTAL(9,P4:P18) -> 0 | Q2: =SUBTOTAL(9,Q4:Q18) -> 0 | R2: =SUBTOTAL(9,R4:R18) -> 0
A3: Наименование подрядчика | B3: Размещение, руб., NET | C3: Производство, руб., NET | D3: Де/монтаж, руб., NET | E3: ИТОГО, руб., NET | F3: ИТОГО, руб., GROSS | G3: НАЛОГ Заказчика | H3: Размещение, руб., NET | I3: Производство, руб., NET | J3: Де/монтаж, руб., NET | K3: ИТОГО, руб., NET | L3: ИТОГО, руб., GROSS | M3: НАЛОГ подрядчика | N3: Размещение, руб., NET | O3: Производство, руб., NET | P3: Де/монтаж, руб., NET | Q3: ИТОГО, руб., NET | R3: ИТОГО, руб., GROSS
B4: =SUMIFS(МП!$CC:$CC,МП!$ES:$ES,$A4) -> 0 | C4: =SUMIFS(МП!$CE:$CE,МП!$ES:$ES,$A4) -> 0 | D4: =SUMIFS(МП!$CG:$CG,МП!$ES:$ES,$A4) -> 0 | E4: =SUM(B4:D4) -> 0 | F4: =E4*(1+G4) -> 0 | G4: =IFERROR(AVERAGEIFS(МП!$CM:$CM,МП!$ES:$ES,$A4),0) -> 0 | H4: =SUMIFS(МП!$EE:$EE,МП!$ES:$ES,$A4) -> 0 | I4: =SUMIFS(МП!$EI:$EI,МП!$ES:$ES,$A4) -> 0 | J4: =SUMIFS(МП!$EL:$EL,МП!$ES:$ES,$A4) -> 0 | K4: =SUM(H4:J4) -> 0 | L4: =K4*(1+M4) -> 0 | M4: =IFERROR(AVERAGEIFS(МП!$EP:$EP,МП!$ES:$ES,$A4),0) -> 0 | N4: =SUMIFS(МП!$EE:$EE,МП!$ES:$ES,$A4,МП!$CV:$CV,"подтверждено") -> 0 | O4: =SUMIFS(МП!$EI:$EI,МП!$ES:$ES,$A4,МП!$CV:$CV,"подтверждено") -> 0 | P4: =SUMIFS(МП!$EL:$EL,МП!$ES:$ES,$A4,МП!$CV:$CV,"подтверждено") -> 0 | Q4: =SUM(N4:P4) -> 0 | R4: =Q4*(1+M4) -> 0
B5: =SUMIFS(МП!$CC:$CC,МП!$ES:$ES,$A5) -> 0 | C5: =SUMIFS(МП!$CE:$CE,МП!$ES:$ES,$A5) -> 0 | D5: =SUMIFS(МП!$CG:$CG,МП!$ES:$ES,$A5) -> 0 | E5: =SUM(B5:D5) -> 0 | F5: =E5*(1+G5) -> 0 | G5: =IFERROR(AVERAGEIFS(МП!$CM:$CM,МП!$ES:$ES,$A5),0) -> 0 | H5: =SUMIFS(МП!$EE:$EE,МП!$ES:$ES,$A5) -> 0 | I5: =SUMIFS(МП!$EI:$EI,МП!$ES:$ES,$A5) -> 0 | J5: =SUMIFS(МП!$EL:$EL,МП!$ES:$ES,$A5) -> 0 | K5: =SUM(H5:J5) -> 0 | L5: =K5*(1+M5) -> 0 | M5: =IFERROR(AVERAGEIFS(МП!$EP:$EP,МП!$ES:$ES,$A5),0) -> 0 | N5: =SUMIFS(МП!$EE:$EE,МП!$ES:$ES,$A5,МП!$CV:$CV,"подтверждено") -> 0 | O5: =SUMIFS(МП!$EI:$EI,МП!$ES:$ES,$A5,МП!$CV:$CV,"подтверждено") -> 0 | P5: =SUMIFS(МП!$EL:$EL,МП!$ES:$ES,$A5,МП!$CV:$CV,"подтверждено") -> 0 | Q5: =SUM(N5:P5) -> 0 | R5: =Q5*(1+M5) -> 0
B6: =SUMIFS(МП!$CC:$CC,МП!$ES:$ES,$A6) -> 0 | C6: =SUMIFS(МП!$CE:$CE,МП!$ES:$ES,$A6) -> 0 | D6: =SUMIFS(МП!$CG:$CG,МП!$ES:$ES,$A6) -> 0 | E6: =SUM(B6:D6) -> 0 | F6: =E6*(1+G6) -> 0 | G6: =IFERROR(AVERAGEIFS(МП!$CM:$CM,МП!$ES:$ES,$A6),0) -> 0 | H6: =SUMIFS(МП!$EE:$EE,МП!$ES:$ES,$A6) -> 0 | I6: =SUMIFS(МП!$EI:$EI,МП!$ES:$ES,$A6) -> 0 | J6: =SUMIFS(МП!$EL:$EL,МП!$ES:$ES,$A6) -> 0 | K6: =SUM(H6:J6) -> 0 | L6: =K6*(1+M6) -> 0 | M6: =IFERROR(AVERAGEIFS(МП!$EP:$EP,МП!$ES:$ES,$A6),0) -> 0 | N6: =SUMIFS(МП!$EE:$EE,МП!$ES:$ES,$A6,МП!$CV:$CV,"подтверждено") -> 0 | O6: =SUMIFS(МП!$EI:$EI,МП!$ES:$ES,$A6,МП!$CV:$CV,"подтверждено") -> 0 | P6: =SUMIFS(МП!$EL:$EL,МП!$ES:$ES,$A6,МП!$CV:$CV,"подтверждено") -> 0 | Q6: =SUM(N6:P6) -> 0 | R6: =Q6*(1+M6) -> 0
B7: =SUMIFS(МП!$CC:$CC,МП!$ES:$ES,$A7) -> 0 | C7: =SUMIFS(МП!$CE:$CE,МП!$ES:$ES,$A7) -> 0 | D7: =SUMIFS(МП!$CG:$CG,МП!$ES:$ES,$A7) -> 0 | E7: =SUM(B7:D7) -> 0 | F7: =E7*(1+G7) -> 0 | G7: =IFERROR(AVERAGEIFS(МП!$CM:$CM,МП!$ES:$ES,$A7),0) -> 0 | H7: =SUMIFS(МП!$EE:$EE,МП!$ES:$ES,$A7) -> 0 | I7: =SUMIFS(МП!$EI:$EI,МП!$ES:$ES,$A7) -> 0 | J7: =SUMIFS(МП!$EL:$EL,МП!$ES:$ES,$A7) -> 0 | K7: =SUM(H7:J7) -> 0 | L7: =K7*(1+M7) -> 0 | M7: =IFERROR(AVERAGEIFS(МП!$EP:$EP,МП!$ES:$ES,$A7),0) -> 0 | N7: =SUMIFS(МП!$EE:$EE,МП!$ES:$ES,$A7,МП!$CV:$CV,"подтверждено") -> 0 | O7: =SUMIFS(МП!$EI:$EI,МП!$ES:$ES,$A7,МП!$CV:$CV,"подтверждено") -> 0 | P7: =SUMIFS(МП!$EL:$EL,МП!$ES:$ES,$A7,МП!$CV:$CV,"подтверждено") -> 0 | Q7: =SUM(N7:P7) -> 0 | R7: =Q7*(1+M7) -> 0
B8: =SUMIFS(МП!$CC:$CC,МП!$ES:$ES,$A8) -> 0 | C8: =SUMIFS(МП!$CE:$CE,МП!$ES:$ES,$A8) -> 0 | D8: =SUMIFS(МП!$CG:$CG,МП!$ES:$ES,$A8) -> 0 | E8: =SUM(B8:D8) -> 0 | F8: =E8*(1+G8) -> 0 | G8: =IFERROR(AVERAGEIFS(МП!$CM:$CM,МП!$ES:$ES,$A8),0) -> 0 | H8: =SUMIFS(МП!$EE:$EE,МП!$ES:$ES,$A8) -> 0 | I8: =SUMIFS(МП!$EI:$EI,МП!$ES:$ES,$A8) -> 0 | J8: =SUMIFS(МП!$EL:$EL,МП!$ES:$ES,$A8) -> 0 | K8: =SUM(H8:J8) -> 0 | L8: =K8*(1+M8) -> 0 | M8: =IFERROR(AVERAGEIFS(МП!$EP:$EP,МП!$ES:$ES,$A8),0) -> 0 | N8: =SUMIFS(МП!$EE:$EE,МП!$ES:$ES,$A8,МП!$CV:$CV,"подтверждено") -> 0 | O8: =SUMIFS(МП!$EI:$EI,МП!$ES:$ES,$A8,МП!$CV:$CV,"подтверждено") -> 0 | P8: =SUMIFS(МП!$EL:$EL,МП!$ES:$ES,$A8,МП!$CV:$CV,"подтверждено") -> 0 | Q8: =SUM(N8:P8) -> 0 | R8: =Q8*(1+M8) -> 0
B9: =SUMIFS(МП!$CC:$CC,МП!$ES:$ES,$A9) -> 0 | C9: =SUMIFS(МП!$CE:$CE,МП!$ES:$ES,$A9) -> 0 | D9: =SUMIFS(МП!$CG:$CG,МП!$ES:$ES,$A9) -> 0 | E9: =SUM(B9:D9) -> 0 | F9: =E9*(1+G9) -> 0 | G9: =IFERROR(AVERAGEIFS(МП!$CM:$CM,МП!$ES:$ES,$A9),0) -> 0 | H9: =SUMIFS(МП!$EE:$EE,МП!$ES:$ES,$A9) -> 0 | I9: =SUMIFS(МП!$EI:$EI,МП!$ES:$ES,$A9) -> 0 | J9: =SUMIFS(МП!$EL:$EL,МП!$ES:$ES,$A9) -> 0 | K9: =SUM(H9:J9) -> 0 | L9: =K9*(1+M9) -> 0 | M9: =IFERROR(AVERAGEIFS(МП!$EP:$EP,МП!$ES:$ES,$A9),0) -> 0 | N9: =SUMIFS(МП!$EE:$EE,МП!$ES:$ES,$A9,МП!$CV:$CV,"подтверждено") -> 0 | O9: =SUMIFS(МП!$EI:$EI,МП!$ES:$ES,$A9,МП!$CV:$CV,"подтверждено") -> 0 | P9: =SUMIFS(МП!$EL:$EL,МП!$ES:$ES,$A9,МП!$CV:$CV,"подтверждено") -> 0 | Q9: =SUM(N9:P9) -> 0 | R9: =Q9*(1+M9) -> 0
B10: =SUMIFS(МП!$CC:$CC,МП!$ES:$ES,$A10) -> 0 | C10: =SUMIFS(МП!$CE:$CE,МП!$ES:$ES,$A10) -> 0 | D10: =SUMIFS(МП!$CG:$CG,МП!$ES:$ES,$A10) -> 0 | E10: =SUM(B10:D10) -> 0 | F10: =E10*(1+G10) -> 0 | G10: =IFERROR(AVERAGEIFS(МП!$CM:$CM,МП!$ES:$ES,$A10),0) -> 0 | H10: =SUMIFS(МП!$EE:$EE,МП!$ES:$ES,$A10) -> 0 | I10: =SUMIFS(МП!$EI:$EI,МП!$ES:$ES,$A10) -> 0 | J10: =SUMIFS(МП!$EL:$EL,МП!$ES:$ES,$A10) -> 0 | K10: =SUM(H10:J10) -> 0 | L10: =K10*(1+M10) -> 0 | M10: =IFERROR(AVERAGEIFS(МП!$EP:$EP,МП!$ES:$ES,$A10),0) -> 0 | N10: =SUMIFS(МП!$EE:$EE,МП!$ES:$ES,$A10,МП!$CV:$CV,"подтверждено") -> 0 | O10: =SUMIFS(МП!$EI:$EI,МП!$ES:$ES,$A10,МП!$CV:$CV,"подтверждено") -> 0 | P10: =SUMIFS(МП!$EL:$EL,МП!$ES:$ES,$A10,МП!$CV:$CV,"подтверждено") -> 0 | Q10: =SUM(N10:P10) -> 0 | R10: =Q10*(1+M10) -> 0
B11: =SUMIFS(МП!$CC:$CC,МП!$ES:$ES,$A11) -> 0 | C11: =SUMIFS(МП!$CE:$CE,МП!$ES:$ES,$A11) -> 0 | D11: =SUMIFS(МП!$CG:$CG,МП!$ES:$ES,$A11) -> 0 | E11: =SUM(B11:D11) -> 0 | F11: =E11*(1+G11) -> 0 | G11: =IFERROR(AVERAGEIFS(МП!$CM:$CM,МП!$ES:$ES,$A11),0) -> 0 | H11: =SUMIFS(МП!$EE:$EE,МП!$ES:$ES,$A11) -> 0 | I11: =SUMIFS(МП!$EI:$EI,МП!$ES:$ES,$A11) -> 0 | J11: =SUMIFS(МП!$EL:$EL,МП!$ES:$ES,$A11) -> 0 | K11: =SUM(H11:J11) -> 0 | L11: =K11*(1+M11) -> 0 | M11: =IFERROR(AVERAGEIFS(МП!$EP:$EP,МП!$ES:$ES,$A11),0) -> 0 | N11: =SUMIFS(МП!$EE:$EE,МП!$ES:$ES,$A11,МП!$CV:$CV,"подтверждено") -> 0 | O11: =SUMIFS(МП!$EI:$EI,МП!$ES:$ES,$A11,МП!$CV:$CV,"подтверждено") -> 0 | P11: =SUMIFS(МП!$EL:$EL,МП!$ES:$ES,$A11,МП!$CV:$CV,"подтверждено") -> 0 | Q11: =SUM(N11:P11) -> 0 | R11: =Q11*(1+M11) -> 0
B12: =SUMIFS(МП!$CC:$CC,МП!$ES:$ES,$A12) -> 0 | C12: =SUMIFS(МП!$CE:$CE,МП!$ES:$ES,$A12) -> 0 | D12: =SUMIFS(МП!$CG:$CG,МП!$ES:$ES,$A12) -> 0 | E12: =SUM(B12:D12) -> 0 | F12: =E12*(1+G12) -> 0 | G12: =IFERROR(AVERAGEIFS(МП!$CM:$CM,МП!$ES:$ES,$A12),0) -> 0 | H12: =SUMIFS(МП!$EE:$EE,МП!$ES:$ES,$A12) -> 0 | I12: =SUMIFS(МП!$EI:$EI,МП!$ES:$ES,$A12) -> 0 | J12: =SUMIFS(МП!$EL:$EL,МП!$ES:$ES,$A12) -> 0 | K12: =SUM(H12:J12) -> 0 | L12: =K12*(1+M12) -> 0 | M12: =IFERROR(AVERAGEIFS(МП!$EP:$EP,МП!$ES:$ES,$A12),0) -> 0 | N12: =SUMIFS(МП!$EE:$EE,МП!$ES:$ES,$A12,МП!$CV:$CV,"подтверждено") -> 0 | O12: =SUMIFS(МП!$EI:$EI,МП!$ES:$ES,$A12,МП!$CV:$CV,"подтверждено") -> 0 | P12: =SUMIFS(МП!$EL:$EL,МП!$ES:$ES,$A12,МП!$CV:$CV,"подтверждено") -> 0 | Q12: =SUM(N12:P12) -> 0 | R12: =Q12*(1+M12) -> 0
B13: =SUMIFS(МП!$CC:$CC,МП!$ES:$ES,$A13) -> 0 | C13: =SUMIFS(МП!$CE:$CE,МП!$ES:$ES,$A13) -> 0 | D13: =SUMIFS(МП!$CG:$CG,МП!$ES:$ES,$A13) -> 0 | E13: =SUM(B13:D13) -> 0 | F13: =E13*(1+G13) -> 0 | G13: =IFERROR(AVERAGEIFS(МП!$CM:$CM,МП!$ES:$ES,$A13),0) -> 0 | H13: =SUMIFS(МП!$EE:$EE,МП!$ES:$ES,$A13) -> 0 | I13: =SUMIFS(МП!$EI:$EI,МП!$ES:$ES,$A13) -> 0 | J13: =SUMIFS(МП!$EL:$EL,МП!$ES:$ES,$A13) -> 0 | K13: =SUM(H13:J13) -> 0 | L13: =K13*(1+M13) -> 0 | M13: =IFERROR(AVERAGEIFS(МП!$EP:$EP,МП!$ES:$ES,$A13),0) -> 0 | N13: =SUMIFS(МП!$EE:$EE,МП!$ES:$ES,$A13,МП!$CV:$CV,"подтверждено") -> 0 | O13: =SUMIFS(МП!$EI:$EI,МП!$ES:$ES,$A13,МП!$CV:$CV,"подтверждено") -> 0 | P13: =SUMIFS(МП!$EL:$EL,МП!$ES:$ES,$A13,МП!$CV:$CV,"подтверждено") -> 0 | Q13: =SUM(N13:P13) -> 0 | R13: =Q13*(1+M13) -> 0
B14: =SUMIFS(МП!$CC:$CC,МП!$ES:$ES,$A14) -> 0 | C14: =SUMIFS(МП!$CE:$CE,МП!$ES:$ES,$A14) -> 0 | D14: =SUMIFS(МП!$CG:$CG,МП!$ES:$ES,$A14) -> 0 | E14: =SUM(B14:D14) -> 0 | F14: =E14*(1+G14) -> 0 | G14: =IFERROR(AVERAGEIFS(МП!$CM:$CM,МП!$ES:$ES,$A14),0) -> 0 | H14: =SUMIFS(МП!$EE:$EE,МП!$ES:$ES,$A14) -> 0 | I14: =SUMIFS(МП!$EI:$EI,МП!$ES:$ES,$A14) -> 0 | J14: =SUMIFS(МП!$EL:$EL,МП!$ES:$ES,$A14) -> 0 | K14: =SUM(H14:J14) -> 0 | L14: =K14*(1+M14) -> 0 | M14: =IFERROR(AVERAGEIFS(МП!$EP:$EP,МП!$ES:$ES,$A14),0) -> 0 | N14: =SUMIFS(МП!$EE:$EE,МП!$ES:$ES,$A14,МП!$CV:$CV,"подтверждено") -> 0 | O14: =SUMIFS(МП!$EI:$EI,МП!$ES:$ES,$A14,МП!$CV:$CV,"подтверждено") -> 0 | P14: =SUMIFS(МП!$EL:$EL,МП!$ES:$ES,$A14,МП!$CV:$CV,"подтверждено") -> 0 | Q14: =SUM(N14:P14) -> 0 | R14: =Q14*(1+M14) -> 0
B15: =SUMIFS(МП!$CC:$CC,МП!$ES:$ES,$A15) -> 0 | C15: =SUMIFS(МП!$CE:$CE,МП!$ES:$ES,$A15) -> 0 | D15: =SUMIFS(МП!$CG:$CG,МП!$ES:$ES,$A15) -> 0 | E15: =SUM(B15:D15) -> 0 | F15: =E15*(1+G15) -> 0 | G15: =IFERROR(AVERAGEIFS(МП!$CM:$CM,МП!$ES:$ES,$A15),0) -> 0 | H15: =SUMIFS(МП!$EE:$EE,МП!$ES:$ES,$A15) -> 0 | I15: =SUMIFS(МП!$EI:$EI,МП!$ES:$ES,$A15) -> 0 | J15: =SUMIFS(МП!$EL:$EL,МП!$ES:$ES,$A15) -> 0 | K15: =SUM(H15:J15) -> 0 | L15: =K15*(1+M15) -> 0 | M15: =IFERROR(AVERAGEIFS(МП!$EP:$EP,МП!$ES:$ES,$A15),0) -> 0 | N15: =SUMIFS(МП!$EE:$EE,МП!$ES:$ES,$A15,МП!$CV:$CV,"подтверждено") -> 0 | O15: =SUMIFS(МП!$EI:$EI,МП!$ES:$ES,$A15,МП!$CV:$CV,"подтверждено") -> 0 | P15: =SUMIFS(МП!$EL:$EL,МП!$ES:$ES,$A15,МП!$CV:$CV,"подтверждено") -> 0 | Q15: =SUM(N15:P15) -> 0 | R15: =Q15*(1+M15) -> 0
... B18: =SUMIFS(МП!$CC:$CC,МП!$ES:$ES,$A18) -> 0 | C18: =SUMIFS(МП!$CE:$CE,МП!$ES:$ES,$A18) -> 0 | D18: =SUMIFS(МП!$CG:$CG,МП!$ES:$ES,$A18) -> 0 | E18: =SUM(B18:D18) -> 0 | F18: =E18*(1+G18) -> 0 | G18: =IFERROR(AVERAGEIFS(МП!$CM:$CM,МП!$ES:$ES,$A18),0) -> 0 | H18: =SUMIFS(МП!$EE:$EE,МП!$ES:$ES,$A18) -> 0 | I18: =SUMIFS(МП!$EI:$EI,МП!$ES:$ES,$A18) -> 0 | J18: =SUMIFS(МП!$EL:$EL,МП!$ES:$ES,$A18) -> 0 | K18: =SUM(H18:J18) -> 0 | L18: =K18*(1+M18) -> 0 | M18: =IFERROR(AVERAGEIFS(МП!$EP:$EP,МП!$ES:$ES,$A18),0) -> 0 | N18: =SUMIFS(МП!$EE:$EE,МП!$ES:$ES,$A18,МП!$CV:$CV,"подтверждено") -> 0 | O18: =SUMIFS(МП!$EI:$EI,МП!$ES:$ES,$A18,МП!$CV:$CV,"подтверждено") -> 0 | P18: =SUMIFS(МП!$EL:$EL,МП!$ES:$ES,$A18,МП!$CV:$CV,"подтверждено") -> 0 | Q18: =SUM(N18:P18) -> 0 | R18: =Q18*(1+M18) -> 0

Sheet МП
DJ1: =IFERROR( IF(#REF!="NovikovTV | НовиковТВ",IF(SUMIFS($DI:$DI,$ES:$ES,"NovikovTV | НовиковТВ")<280000, (SUMIFS($DI:$DI,$ES:$ES,"NovikovTV | НовиковТВ")/ (COUNTIFS($ES:$ES,"NovikovTV | НовиковТВ")))*280000/ SUMIFS($DI:$DI,$ES:$ES,"NovikovTV | НовиковТВ")),0)+#REF!/( 1-(1-( IF(#REF!="NovikovTV | НовиковТВ",IF(SUMIFS($DI:$DI,$ES:$ES,"NovikovTV | НовиковТВ")<280000, (SUMIFS($DI:$DI,$ES:$ES,"NovikovTV | НовиковТВ")/ (COUNTIFS($ES:$ES,"NovikovTV | НовиковТВ")))*280000/ SUMIFS($DI:$DI,$ES:$ES,"NovikovTV | НовиковТВ")),0))* (1-#REF!)*(1-#REF!)*(1-#REF!)*(1-#REF!)*(1-#REF!)/ IF(#REF!="NovikovTV | НовиковТВ",IF(SUMIFS($DI:$DI,$ES:$ES,"NovikovTV | НовиковТВ")<280000, (SUMIFS($DI:$DI,$ES:$ES,"NovikovTV | НовиковТВ")/ (COUNTIFS($ES:$ES,"NovikovTV | НовиковТВ")))*280000/ SUMIFS($DI:$DI,$ES:$ES,"NovikovTV | НовиковТВ")),0))),0) -> 0
M2: ПРИМЕЧАНИЕ:
M3: 1. Условия актуальны при наличии свободных мест, в течение 7 календарных дней после выставления настоящего предложения (далее по тексту - КП). Резервирование осуществляется по запросу.
E4: Заказчик: | M4: 2. Условия актуальны в рамках расчетного периода, объема и указанных характеристик. В случае изменения параметров условия подлежат пересмотру.
E5: ГЕО/привязка: | M5: 3. Условия предоставлены под указанного заказчика и бренд, без эксклюзива по товарной категории. При изменении заказчика и бренда, или проведения тендера по выбранной адресной программе, без предварительного уведомления, указанные условия будут отозваны и пересмотрены.
E6: Период: | F6: {=IFERROR( _xlfn.IFS( SUBTOTAL(9,AW:AW)=0,"", SUBTOTAL(9,AX:AX)=0,"", SUBTOTAL(9,AW:AW)+SUBTOTAL(9,AX:AX)=0,"", SUBTOTAL(9,AW:AW)+SUBTOTAL(9,AX:AX)<>0, CONCATENATE(TEXT(MIN(AW:AW),"ДД.ММ.ГГГГ"),"-",TEXT(MAX(AX:AX),"ДД.ММ.ГГГГ"))),"")} | M6: 4. Производство макетов РИМ осуществляется собственными силами заказчика и не включено в настоящее предложение, если иное не указано в КП. | DM6: _- агентская скидка (для РА)
E7: Формат: | M7: 5. Обозначение NET соответствует условиям "без НДС", обозначение GROSS соответствует условиям "в том числе НДС". | DM7: _- скидка за период
E8: ПОДСВЕТКА: | F8: ВКЛ | M8: 6. Поставщик оставляет за собой право отказать в размещении рекламы без объяснения причин. | DM8: _- скидка за объем
M9: 7. Адреса, кол-во точек распространения/вещания, кол-во РН на момент финального подтверждения могут быть скорректированы. | DM9: _- welcom скидка
E10: Предложение действует до: | F10: =TODAY()+6 -> 45858 | M10: 8. Не является публичной офертой. | DM10: _- спец. скидка
X12: =SUBTOTAL(9,AW:AW)+SUBTOTAL(9,AX:AX) -> 0 | BN12: КЛИЕНТ | CV12: БАИНГ
CU13: _ ->|!!!УДАЛИТЬ ПЕРЕД ОТПРАВКОЙ ЗАКАЗЧИКУ | DG13: =IF($DC13=0,0,$DD13*($DC13*100%-$DE13*$DF13))*$AB13 -> 0 | DI13: {=IFERROR( IF($ES13="LisChannel", (ROUND(((INDEX({174.625;153.888888888889;130.972222222222},MATCH($AI13,{2;3;4}),0))*$AG13*$AI13),2)),0),0)} -> 0 | DJ13: =IFERROR( IF( $ES13<>"НовиковТВ", $DI13+$DG13/(1-(1-($DI13)*(1-$DL13)*(1-$DM13)*(1-$DN13)*(1-$DO13)*(1-$DP13)/$DI13)), _xlfn.LET(_xlpm.NTV, _xlfn.LET(_xlpm.MIN, 280000 +N("МИНИМАЛЬНЫЙ ПАКЕТ"), IF($ES13="НовиковТВ",IF(SUMIFS($DI:$DI,$ES:$ES,"НовиковТВ")<_xlpm.MIN, (SUMIFS($DI:$DI,$ES:$ES,"НовиковТВ")/(COUNTIFS($ES:$ES,"НовиковТВ")))*_xlpm.MIN/SUMIFS($DI:$DI,$ES:$ES,"НовиковТВ")), 0)), _xlpm.NTV+$DG13/(1-(1-(_xlpm.NTV)*(1-$DL13)*(1-$DM13)*(1-$DN13)*(1-$DO13)*(1-$DP13)/_xlpm.NTV)))), 0) -> 0 | DQ13: {=IFERROR(_xlfn.IFS( $DK13="послед.",1-(1-$DL13)*(1-$DM13)*(1-$DN13)*(1-$DO13)*(1-$DP13), $DK13="сумм.",$DL13+$DM13+$DN13+$DO13+$DP13), 0)} -> 0 | DR13: {=IF(DQ13>0, IFERROR( _xlfn.IFS($BL13=0, 0, $BL13>0, _xlfn.IFS(DK13="послед.", $DJ13*(1-$DL13)*(1-$DM13)*(1-$DN13)*(1-$DO13)*(1-$DP13), DK13="сумм", $DJ13*(1-($DL13+$DM13+$DN13+$DO13+$DP13)))), 0), $DJ13)} -> 0 | DS13: {=IFERROR(_xlfn.IFS( $DH13="день_1", $DR13*$BL13/($AZ$14*$AY11+$BA$14*$BA13+$BB$14*$BB13+$BC$14*$BC13+$BD$14*$BD13+$BE$14*$BE13+$BF$14*$BF13+$BG$14*$BG13+$BH$14*$BH13+$BI$14*$BI13+$BJ$14*$BJ13+$BK$14*$BK13)*AY11*AZ$14, $DH13="день_2", $DR13/30*AY11*AZ$14, $DH13="день_3", $DR13/30*MAX(MIN($AX13,EOMONTH(AZ$15,0))-MAX($AW13,AZ$15)+1,), $DH13="раб.день", $DR13/30*( _xlfn.LET(_xlpm.VD, CHOOSE( {1;2;3;4;5;6;7;8;9;10;11;12;13;14;15;16}, 45658,45659,45660,45661,45662,45663,45664,45665,45711,45724,45778,45779,45786,45820,45821,45965,46022), _xlfn.LET(_xlpm.DD, MAX(MIN($AX13,EOMONTH(AZ$15,0))-MAX($AW13,AZ$15)+1,), _xlfn.IFS( AND(MONTH($AW13)=MONTH(AZ$15),MONTH($AX13)<>MONTH(AZ$15)), NETWORKDAYS.INTL(($AX13+1)-_xlpm.DD,$AX13,1,_xlpm.VD), AND(MONTH($AW13)=MONTH(AZ$15),MONTH($AX13)=MONTH(AZ$15)), NETWORKDAYS.INTL($AW13,$AX13,1,_xlpm.VD), AND(MONTH($AW13)<>MONTH(AZ$15),MONTH($AX13)=MONTH(AZ$15)), NETWORKDAYS.INTL(($AX13+1)-_xlpm.DD,$AX13,1,_xlpm.VD), AND(MONTH($AW13)<MONTH(AZ$15),MONTH($AX13)>MONTH(AZ$15)), NETWORKDAYS.INTL((EOMONTH(AZ$15-1,1)+1)-_xlpm.DD,EOMONTH(AZ$15-1,1),1,_xlpm.VD) )))), $DH13="месяц", $DR13*AY11, $DH13="неделя", $DR13*AY11/7*(ROUNDUP(AZ$14/4,0))), 0)} -> 0 | DT13: {=IFERROR(_xlfn.IFS( $DH13="день_1", $DR13*$BL13/($AZ$14*$AY11+$BA$14*$BA13+$BB$14*$BB13+$BC$14*$BC13+$BD$14*$BD13+$BE$14*$BE13+$BF$14*$BF13+$BG$14*$BG13+$BH$14*$BH13+$BI$14*$BI13+$BJ$14*$BJ13+$BK$14*$BK13)*BA13*BA$14, $DH13="день_2", $DR13/30*BA13*BA$14, $DH13="день_3", $DR13/30*MAX(MIN($AX13,EOMONTH(BA$15,0))-MAX($AW13,BA$15)+1,), $DH13="раб.день", $DR13/30*( _xlfn.LET(_xlpm.VD, CHOOSE( {1;2;3;4;5;6;7;8;9;10;11;12;13;14;15;16}, 45658,45659,45660,45661,45662,45663,45664,45665,45711,45724,45778,45779,45786,45820,45821,45965,46022), _xlfn.LET(_xlpm.DD, MAX(MIN($AX13,EOMONTH(BA$15,0))-MAX($AW13,BA$15)+1,), _xlfn.IFS( AND(MONTH($AW13)=MONTH(BA$15),MONTH($AX13)<>MONTH(BA$15)), NETWORKDAYS.INTL(($AX13+1)-_xlpm.DD,$AX13,1,_xlpm.VD), AND(MONTH($AW13)=MONTH(BA$15),MONTH($AX13)=MONTH(BA$15)), NETWORKDAYS.INTL($AW13,$AX13,1,_xlpm.VD), AND(MONTH($AW13)<>MONTH(BA$15),MONTH($AX13)=MONTH(BA$15)), NETWORKDAYS.INTL(($AX13+1)-_xlpm.DD,$AX13,1,_xlpm.VD), AND(MONTH($AW13)<MONTH(BA$15),MONTH($AX13)>MONTH(BA$15)), NETWORKDAYS.INTL((EOMONTH(BA$15-1,1)+1)-_xlpm.DD,EOMONTH(BA$15-1,1),1,_xlpm.VD) )))), $DH13="месяц", $DR13*BA13, $DH13="неделя", $DR13*BA13/7*(ROUNDUP(BA$14/4,0))), 0)} -> 0 | DU13: {=IFERROR(_xlfn.IFS( $DH13="день_1", $DR13*$BL13/($AZ$14*$AY11+$BA$14*$BA13+$BB$14*$BB13+$BC$14*$BC13+$BD$14*$BD13+$BE$14*$BE13+$BF$14*$BF13+$BG$14*$BG13+$BH$14*$BH13+$BI$14*$BI13+$BJ$14*$BJ13+$BK$14*$BK13)*BB13*BB$14, $DH13="день_2", $DR13/30*BB13*BB$14, $DH13="день_3", $DR13/30*MAX(MIN($AX13,EOMONTH(BB$15,0))-MAX($AW13,BB$15)+1,), $DH13="раб.день", $DR13/30*( _xlfn.LET(_xlpm.VD, CHOOSE( {1;2;3;4;5;6;7;8;9;10;11;12;13;14;15;16}, 45658,45659,45660,45661,45662,45663,45664,45665,45711,45724,45778,45779,45786,45820,45821,45965,46022), _xlfn.LET(_xlpm.DD, MAX(MIN($AX13,EOMONTH(BB$15,0))-MAX($AW13,BB$15)+1,), _xlfn.IFS( AND(MONTH($AW13)=MONTH(BB$15),MONTH($AX13)<>MONTH(BB$15)), NETWORKDAYS.INTL(($AX13+1)-_xlpm.DD,$AX13,1,_xlpm.VD), AND(MONTH($AW13)=MONTH(BB$15),MONTH($AX13)=MONTH(BB$15)), NETWORKDAYS.INTL($AW13,$AX13,1,_xlpm.VD), AND(MONTH($AW13)<>MONTH(BB$15),MONTH($AX13)=MONTH(BB$15)), NETWORKDAYS.INTL(($AX13+1)-_xlpm.DD,$AX13,1,_xlpm.VD), AND(MONTH($AW13)<MONTH(BB$15),MONTH($AX13)>MONTH(BB$15)), NETWORKDAYS.INTL((EOMONTH(BB$15-1,1)+1)-_xlpm.DD,EOMONTH(BB$15-1,1),1,_xlpm.VD) )))), $DH13="месяц", $DR13*BB13, $DH13="неделя", $DR13*BB13/7*(ROUNDUP(BB$14/4,0))), 0)} -> 0 | DV13: {=IFERROR(_xlfn.IFS( $DH13="день_1", $DR13*$BL13/($AZ$14*$AY11+$BA$14*$BA13+$BB$14*$BB13+$BC$14*$BC13+$BD$14*$BD13+$BE$14*$BE13+$BF$14*$BF13+$BG$14*$BG13+$BH$14*$BH13+$BI$14*$BI13+$BJ$14*$BJ13+$BK$14*$BK13)*BC13*BC$14, $DH13="день_2", $DR13/30*BC13*BC$14, $DH13="день_3", $DR13/30*MAX(MIN($AX13,EOMONTH(BC$15,0))-MAX($AW13,BC$15)+1,), $DH13="раб.день", $DR13/30*( _xlfn.LET(_xlpm.VD, CHOOSE( {1;2;3;4;5;6;7;8;9;10;11;12;13;14;15;16}, 45658,45659,45660,45661,45662,45663,45664,45665,45711,45724,45778,45779,45786,45820,45821,45965,46022), _xlfn.LET(_xlpm.DD, MAX(MIN($AX13,EOMONTH(BC$15,0))-MAX($AW13,BC$15)+1,), _xlfn.IFS( AND(MONTH($AW13)=MONTH(BC$15),MONTH($AX13)<>MONTH(BC$15)), NETWORKDAYS.INTL(($AX13+1)-_xlpm.DD,$AX13,1,_xlpm.VD), AND(MONTH($AW13)=MONTH(BC$15),MONTH($AX13)=MONTH(BC$15)), NETWORKDAYS.INTL($AW13,$AX13,1,_xlpm.VD), AND(MONTH($AW13)<>MONTH(BC$15),MONTH($AX13)=MONTH(BC$15)), NETWORKDAYS.INTL(($AX13+1)-_xlpm.DD,$AX13,1,_xlpm.VD), AND(MONTH($AW13)<MONTH(BC$15),MONTH($AX13)>MONTH(BC$15)), NETWORKDAYS.INTL((EOMONTH(BC$15-1,1)+1)-_xlpm.DD,EOMONTH(BC$15-1,1),1,_xlpm.VD) )))), $DH13="месяц", $DR13*BC13, $DH13="неделя", $DR13*BC13/7*(ROUNDUP(BC$14/4,0))), 0)} -> 0 | DW13: {=IFERROR(_xlfn.IFS( $DH13="день_1", $DR13*$BL13/($AZ$14*$AY11+$BA$14*$BA13+$BB$14*$BB13+$BC$14*$BC13+$BD$14*$BD13+$BE$14*$BE13+$BF$14*$BF13+$BG$14*$BG13+$BH$14*$BH13+$BI$14*$BI13+$BJ$14*$BJ13+$BK$14*$BK13)*BD13*BD$14, $DH13="день_2", $DR13/30*BD13*BD$14, $DH13="день_3", $DR13/30*MAX(MIN($AX13,EOMONTH(BD$15,0))-MAX($AW13,BD$15)+1,), $DH13="раб.день", $DR13/30*( _xlfn.LET(_xlpm.VD, CHOOSE( {1;2;3;4;5;6;7;8;9;10;11;12;13;14;15;16}, 45658,45659,45660,45661,45662,45663,45664,45665,45711,45724,45778,45779,45786,45820,45821,45965,46022), _xlfn.LET(_xlpm.DD, MAX(MIN($AX13,EOMONTH(BD$15,0))-MAX($AW13,BD$15)+1,), _xlfn.IFS( AND(MONTH($AW13)=MONTH(BD$15),MONTH($AX13)<>MONTH(BD$15)), NETWORKDAYS.INTL(($AX13+1)-_xlpm.DD,$AX13,1,_xlpm.VD), AND(MONTH($AW13)=MONTH(BD$15),MONTH($AX13)=MONTH(BD$15)), NETWORKDAYS.INTL($AW13,$AX13,1,_xlpm.VD), AND(MONTH($AW13)<>MONTH(BD$15),MONTH($AX13)=MONTH(BD$15)), NETWORKDAYS.INTL(($AX13+1)-_xlpm.DD,$AX13,1,_xlpm.VD), AND(MONTH($AW13)<MONTH(BD$15),MONTH($AX13)>MONTH(BD$15)), NETWORKDAYS.INTL((EOMONTH(BD$15-1,1)+1)-_xlpm.DD,EOMONTH(BD$15-1,1),1,_xlpm.VD) )))), $DH13="месяц", $DR13*BD13, $DH13="неделя", $DR13*BD13/7*(ROUNDUP(BD$14/4,0))), 0)} -> 0 | DX13: {=IFERROR(_xlfn.IFS( $DH13="день_1", $DR13*$BL13/($AZ$14*$AY11+$BA$14*$BA13+$BB$14*$BB13+$BC$14*$BC13+$BD$14*$BD13+$BE$14*$BE13+$BF$14*$BF13+$BG$14*$BG13+$BH$14*$BH13+$BI$14*$BI13+$BJ$14*$BJ13+$BK$14*$BK13)*BE13*BE$14, $DH13="день_2", $DR13/30*BE13*BE$14, $DH13="день_3", $DR13/30*MAX(MIN($AX13,EOMONTH(BE$15,0))-MAX($AW13,BE$15)+1,), $DH13="раб.день", $DR13/30*( _xlfn.LET(_xlpm.VD, CHOOSE( {1;2;3;4;5;6;7;8;9;10;11;12;13;14;15;16}, 45658,45659,45660,45661,45662,45663,45664,45665,45711,45724,45778,45779,45786,45820,45821,45965,46022), _xlfn.LET(_xlpm.DD, MAX(MIN($AX13,EOMONTH(BE$15,0))-MAX($AW13,BE$15)+1,), _xlfn.IFS( AND(MONTH($AW13)=MONTH(BE$15),MONTH($AX13)<>MONTH(BE$15)), NETWORKDAYS.INTL(($AX13+1)-_xlpm.DD,$AX13,1,_xlpm.VD), AND(MONTH($AW13)=MONTH(BE$15),MONTH($AX13)=MONTH(BE$15)), NETWORKDAYS.INTL($AW13,$AX13,1,_xlpm.VD), AND(MONTH($AW13)<>MONTH(BE$15),MONTH($AX13)=MONTH(BE$15)), NETWORKDAYS.INTL(($AX13+1)-_xlpm.DD,$AX13,1,_xlpm.VD), AND(MONTH($AW13)<MONTH(BE$15),MONTH($AX13)>MONTH(BE$15)), NETWORKDAYS.INTL((EOMONTH(BE$15-1,1)+1)-_xlpm.DD,EOMONTH(BE$15-1,1),1,_xlpm.VD) )))), $DH13="месяц", $DR13*BE13, $DH13="неделя", $DR13*BE13/7*(ROUNDUP(BE$14/4,0))), 0)} -> 0 | DY13: {=IFERROR(_xlfn.IFS( $DH13="день_1", $DR13*$BL13/($AZ$14*$AY11+$BA$14*$BA13+$BB$14*$BB13+$BC$14*$BC13+$BD$14*$BD13+$BE$14*$BE13+$BF$14*$BF13+$BG$14*$BG13+$BH$14*$BH13+$BI$14*$BI13+$BJ$14*$BJ13+$BK$14*$BK13)*BF13*BF$14, $DH13="день_2", $DR13/30*BF13*BF$14, $DH13="день_3", $DR13/30*MAX(MIN($AX13,EOMONTH(BF$15,0))-MAX($AW13,BF$15)+1,), $DH13="раб.день", $DR13/30*( _xlfn.LET(_xlpm.VD, CHOOSE( {1;2;3;4;5;6;7;8;9;10;11;12;13;14;15;16}, 45658,45659,45660,45661,45662,45663,45664,45665,45711,45724,45778,45779,45786,45820,45821,45965,46022), _xlfn.LET(_xlpm.DD, MAX(MIN($AX13,EOMONTH(BF$15,0))-MAX($AW13,BF$15)+1,), _xlfn.IFS( AND(MONTH($AW13)=MONTH(BF$15),MONTH($AX13)<>MONTH(BF$15)), NETWORKDAYS.INTL(($AX13+1)-_xlpm.DD,$AX13,1,_xlpm.VD), AND(MONTH($AW13)=MONTH(BF$15),MONTH($AX13)=MONTH(BF$15)), NETWORKDAYS.INTL($AW13,$AX13,1,_xlpm.VD), AND(MONTH($AW13)<>MONTH(BF$15),MONTH($AX13)=MONTH(BF$15)), NETWORKDAYS.INTL(($AX13+1)-_xlpm.DD,$AX13,1,_xlpm.VD), AND(MONTH($AW13)<MONTH(BF$15),MONTH($AX13)>MONTH(BF$15)), NETWORKDAYS.INTL((EOMONTH(BF$15-1,1)+1)-_xlpm.DD,EOMONTH(BF$15-1,1),1,_xlpm.VD) )))), $DH13="месяц", $DR13*BF13, $DH13="неделя", $DR13*BF13/7*(ROUNDUP(BF$14/4,0))), 0)} -> 0 | DZ13: {=IFERROR(_xlfn.IFS( $DH13="день_1", $DR13*$BL13/($AZ$14*$AY11+$BA$14*$BA13+$BB$14*$BB13+$BC$14*$BC13+$BD$14*$BD13+$BE$14*$BE13+$BF$14*$BF13+$BG$14*$BG13+$BH$14*$BH13+$BI$14*$BI13+$BJ$14*$BJ13+$BK$14*$BK13)*BG13*BG$14, $DH13="день_2", $DR13/30*BG13*BG$14, $DH13="день_3", $DR13/30*MAX(MIN($AX13,EOMONTH(BG$15,0))-MAX($AW13,BG$15)+1,), $DH13="раб.день", $DR13/30*( _xlfn.LET(_xlpm.VD, CHOOSE( {1;2;3;4;5;6;7;8;9;10;11;12;13;14;15;16}, 45658,45659,45660,45661,45662,45663,45664,45665,45711,45724,45778,45779,45786,45820,45821,45965,46022), _xlfn.LET(_xlpm.DD, MAX(MIN($AX13,EOMONTH(BG$15,0))-MAX($AW13,BG$15)+1,), _xlfn.IFS( AND(MONTH($AW13)=MONTH(BG$15),MONTH($AX13)<>MONTH(BG$15)), NETWORKDAYS.INTL(($AX13+1)-_xlpm.DD,$AX13,1,_xlpm.VD), AND(MONTH($AW13)=MONTH(BG$15),MONTH($AX13)=MONTH(BG$15)), NETWORKDAYS.INTL($AW13,$AX13,1,_xlpm.VD), AND(MONTH($AW13)<>MONTH(BG$15),MONTH($AX13)=MONTH(BG$15)), NETWORKDAYS.INTL(($AX13+1)-_xlpm.DD,$AX13,1,_xlpm.VD), AND(MONTH($AW13)<MONTH(BG$15),MONTH($AX13)>MONTH(BG$15)), NETWORKDAYS.INTL((EOMONTH(BG$15-1,1)+1)-_xlpm.DD,EOMONTH(BG$15-1,1),1,_xlpm.VD) )))), $DH13="месяц", $DR13*BG13, $DH13="неделя", $DR13*BG13/7*(ROUNDUP(BG$14/4,0))), 0)} -> 0 | EA13: {=IFERROR(_xlfn.IFS( $DH13="день_1", $DR13*$BL13/($AZ$14*$AY11+$BA$14*$BA13+$BB$14*$BB13+$BC$14*$BC13+$BD$14*$BD13+$BE$14*$BE13+$BF$14*$BF13+$BG$14*$BG13+$BH$14*$BH13+$BI$14*$BI13+$BJ$14*$BJ13+$BK$14*$BK13)*BH13*BH$14, $DH13="день_2", $DR13/30*BH13*BH$14, $DH13="день_3", $DR13/30*MAX(MIN($AX13,EOMONTH(BH$15,0))-MAX($AW13,BH$15)+1,), $DH13="раб.день", $DR13/30*( _xlfn.LET(_xlpm.VD, CHOOSE( {1;2;3;4;5;6;7;8;9;10;11;12;13;14;15;16}, 45658,45659,45660,45661,45662,45663,45664,45665,45711,45724,45778,45779,45786,45820,45821,45965,46022), _xlfn.LET(_xlpm.DD, MAX(MIN($AX13,EOMONTH(BH$15,0))-MAX($AW13,BH$15)+1,), _xlfn.IFS( AND(MONTH($AW13)=MONTH(BH$15),MONTH($AX13)<>MONTH(BH$15)), NETWORKDAYS.INTL(($AX13+1)-_xlpm.DD,$AX13,1,_xlpm.VD), AND(MONTH($AW13)=MONTH(BH$15),MONTH($AX13)=MONTH(BH$15)), NETWORKDAYS.INTL($AW13,$AX13,1,_xlpm.VD), AND(MONTH($AW13)<>MONTH(BH$15),MONTH($AX13)=MONTH(BH$15)), NETWORKDAYS.INTL(($AX13+1)-_xlpm.DD,$AX13,1,_xlpm.VD), AND(MONTH($AW13)<MONTH(BH$15),MONTH($AX13)>MONTH(BH$15)), NETWORKDAYS.INTL((EOMONTH(BH$15-1,1)+1)-_xlpm.DD,EOMONTH(BH$15-1,1),1,_xlpm.VD) )))), $DH13="месяц", $DR13*BH13, $DH13="неделя", $DR13*BH13/7*(ROUNDUP(BH$14/4,0))), 0)} -> 0 | ... ED13: {=IFERROR(_xlfn.IFS( $DH13="день_1", $DR13*$BL13/($AZ$14*$AY11+$BA$14*$BA13+$BB$14*$BB13+$BC$14*$BC13+$BD$14*$BD13+$BE$14*$BE13+$BF$14*$BF13+$BG$14*$BG13+$BH$14*$BH13+$BI$14*$BI13+$BJ$14*$BJ13+$BK$14*$BK13)*BK13*BK$14, $DH13="день_2", $DR13/30*BK13*BK$14, $DH13="день_3", $DR13/30*MAX(MIN($AX13,EOMONTH(BK$15,0))-MAX($AW13,BK$15)+1,), $DH13="раб.день", $DR13/30*( _xlfn.LET(_xlpm.VD, CHOOSE( {1;2;3;4;5;6;7;8;9;10;11;12;13;14;15;16}, 45658,45659,45660,45661,45662,45663,45664,45665,45711,45724,45778,45779,45786,45820,45821,45965,46022), _xlfn.LET(_xlpm.DD, MAX(MIN($AX13,EOMONTH(BK$15,0))-MAX($AW13,BK$15)+1,), _xlfn.IFS( AND(MONTH($AW13)=MONTH(BK$15),MONTH($AX13)<>MONTH(BK$15)), NETWORKDAYS.INTL(($AX13+1)-_xlpm.DD,$AX13,1,_xlpm.VD), AND(MONTH($AW13)=MONTH(BK$15),MONTH($AX13)=MONTH(BK$15)), NETWORKDAYS.INTL($AW13,$AX13,1,_xlpm.VD), AND(MONTH($AW13)<>MONTH(BK$15),MONTH($AX13)=MONTH(BK$15)), NETWORKDAYS.INTL(($AX13+1)-_xlpm.DD,$AX13,1,_xlpm.VD), AND(MONTH($AW13)<MONTH(BK$15),MONTH($AX13)>MONTH(BK$15)), NETWORKDAYS.INTL((EOMONTH(BK$15-1,1)+1)-_xlpm.DD,EOMONTH(BK$15-1,1),1,_xlpm.VD) )))), $DH13="месяц", $DR13*BK13, $DH13="неделя", $DR13*BK13/7*(ROUNDUP(BK$14/4,0))), 0)} -> 0
D14: {=IFERROR( INDEX(CHOOSE( {1;2;3;4;5;6;7;8;9;10;11;12;13;14;15;16;17;18;19;20;21;22;23;24;25;26;27;28;29;30;31;32;33;34;35;36;37;38;39;40;41;42;43;44;45;46;47;48;49;50;51;52;53;54;55;56;57;58;59;60;61;62;63;64;65;66;67;68;69;70;71;72;73;74;75;76;77;78;79;80;81;82;83}, "ЦФО","СЗФО","ЮФО","УрФО","ЮФО","ПФО","ПФО","УрФО","ПФО","ПФО","СКФО","СФО","СКФО","СФО","СФО","ПФО","ЮФО","ПФО","СФО","ЦФО","СФО","ПФО","СФО","ЮФО","ДФО","УрФО","УрФО","ЦФО","СКФО","ПФО","ЦФО","ЦФО","ДФО","ПФО","ПФО","ЦФО","ЦФО","ПФО","ПФО","ЦФО","СЗФО","ЦФО","ЦФО","ЦФО","СЗФО","СФО","ДФО","СЗФО","ЦФО","ЮФО","ЦФО","ЦФО","ДФО","ДФО","ЦФО","СКФО","УрФО","СЗФО","ДФО","ПФО","СЗФО","ЦФО","СКФО","ПФО","ЦФО","СЗФО","СЗФО","СЗФО","УрФО","СФО","СКФО","ЮФО","ДФО","СКФО","ЮФО","СФО","ДФО","ЮФО","СФО","ДФО","ДФО","ДФО","СЗФО"), MATCH($E14, {"Московская Область";"Ленинградская область";"Краснодарский край";"Свердловская Область";"Ростовская Область";"Башкортостан Республика";"Татарстан Республика";"Челябинская Область";"Нижегородская Область";"Самарская Область";"Дагестан Республика";"Красноярский Край";"Ставропольский Край";"Новосибирская Область";"Кемеровская Область";"Пермский Край";"Волгоградская Область";"Саратовская Область";"Иркутская Область";"Воронежская Область";"Алтайский Край";"Оренбургская Область";"Омская Область";"Крым Республика";"Приморский Край";"Ханты-Мансийский Автономный округ - Югра Автономный округ";"Тюменская Область";"Белгородская Область";"Чеченская Республика";"Удмуртская Республика";"Тульская Область";"Владимирская Область";"Хабаровский Край";"Пензенская Область";"Кировская Область";"Тверская Область";"Ярославская Область";"Ульяновская Область";"Чувашская Республика - Чувашия";"Брянская Область";"Вологодская Область";"Липецкая Область";"Рязанская Область";"Курская Область";"Архангельская Область";"Томская Область";"Забайкальский Край";"Калининградская Область";"Калужская Область";"Астраханская Область";"Тамбовская Область";"Ивановская Область";"Бурятия Республика";"Саха (Якутия) Республика";"Смоленская Область";"Кабардино-Балкарская Республика";"Курганская Область";"Коми Республика";"Амурская Область";"Мордовия Республика";"Мурманская Область";"Орловская Область";"Северная Осетия - Алания Республика";"Марий Эл Республика";"Костромская Область";"Псковская Область";"Карелия Республика";"Новгородская Область";"Ямало-Ненецкий Автономный округ";"Хакасия Республика";"Ингушетия Республика";"Севастополь Город";"Сахалинская Область";"Карачаево-Черкесская Республика";"Адыгея Республика";"Тыва Республика";"Камчатский Край";"Калмыкия Республика";"Алтай Республика";"Еврейская Автономная область";"Магаданская Область";"Чукотский Автономный округ";"Ненецкий Автономный округ"}, 0)),"")} | E14: {=IFERROR( INDEX(CHOOSE( {1;2;3;4;5;6;7;8;9;10;11;12;13;14;15;16;17;18;19;20;21;22;23;24;25;26;27;28;29;30;31;32;33;34;35;36;37;38;39;40;41;42;43;44;45;46}, "Краснодарский край","Приморский Край","Нижегородская Область","Саратовская Область","Красноярский Край","Самарская Область","Ленинградская область","Свердловская Область","Московская Область","Московская Область","Новосибирская Область","Тюменская Область","Волгоградская Область","Волгоградская Область","Воронежская Область","Удмуртская Республика","Татарстан Республика","Кемеровская Область","Краснодарский край","Омская Область","Пермский Край","Ростовская Область","Башкортостан Республика","Хабаровский Край","Чувашская Республика - Чувашия","Челябинская Область","Ярославская Область","Алтайский Край","Иркутская Область","Кемеровская Область","Оренбургская Область","Рязанская Область","Самарская Область","Томская Область","Ульяновская Область","Омская Область","Пермский Край","Челябинская Область","Ярославская Область","Тюменская Область","Алтайский Край","Томская Область","Волгоградская Область","Кемеровская Область","Новосибирская Область","Татарстан республика"), MATCH($F14, {"Сочи";"Владивосток";"Нижний Новгород";"Саратов";"Красноярск";"Самара";"Санкт-Петербург";"Екатеринбург";"Москва";"Химки";"Новосибирск";"Тюмень";"Волгоград";"Волжский";"Воронеж";"Ижевск";"Казань";"Кемерово";"Краснодар";"Омск";"Пермь";"Ростов-на-Дону";"Уфа";"Хабаровск";"Чебоксары";"Челябинск";"Ярославль";"Барнаул";"Иркутск";"Новокузнецк";"Оренбург";"Рязань";"Тольятти";"Томск";"Ульяновск";"Омск";"Пермь";"Челябинск";"Ярославль";"Тюмень";"Барнаул";"Томск";"Волгоград";"Кемерово";"Новосибирск";"Набережные Челны"}, 0)),"")} | H14: {=IFERROR( INDEX(CHOOSE( {1;2;3;4;5;6;7;8;9;10;11;12;13;14;15;16;17;18;19;20;21;22;23;24;25;26;27;28;29;30;31;32;33;34;35;36;37;38;39;40;41;42;43;44;45;46;47;48;49;50;51;52;53;54;55;56;57;58;59;60;61;62;63;64;65;66;67;68;69;70;71;72;73;74;75;76;77;78;79;80;81;82;83;84;85;86;87;88;89;90;91;92;93;94;95;96;97;98;99;100;101;102;103;104;105;106;107;108;109;110;111;112;113;114;115;116;117;118;119;120;121;122;123;124;125;126;127}, "ЦАО","ЦАО","ЦАО","ЦАО","ЦАО","ЦАО","ЦАО","ЦАО","ЦАО","ЦАО","САО","САО","САО","САО","САО","САО","САО","САО","САО","САО","САО","САО","САО","САО","САО","САО","СВАО","СВАО","СВАО","СВАО","СВАО","СВАО","СВАО","СВАО","СВАО","СВАО","СВАО","СВАО","СВАО","СВАО","СВАО","СВАО","СВАО","ВАО","ВАО","ВАО","ВАО","ВАО","ВАО","ВАО","ВАО","ВАО","ВАО","ВАО","ВАО","ВАО","ВАО","ВАО","ВАО","ВАО","ВАО","ЮВАО","ЮВАО","ЮВАО","ЮВАО","ЮВАО","ЮВАО","ЮВАО","ЮВАО","ЮВАО","ЮВАО","ЮВАО","ЮВАО","ЮАО","ЮАО","ЮАО","ЮАО","ЮАО","ЮАО","ЮАО","ЮАО","ЮАО","ЮАО","ЮАО","ЮАО","ЮАО","ЮАО","ЮАО","ЮАО","ЮЗАО","ЮЗАО","ЮЗАО","ЮЗАО","ЮЗАО","ЮЗАО","ЮЗАО","ЮЗАО","ЮЗАО","ЮЗАО","ЮЗАО","ЮЗАО","ЗАО","ЗАО","ЗАО","ЗАО","ЗАО","ЗАО","ЗАО","ЗАО","ЗАО","ЗАО","ЗАО","ЗАО","ЗАО","СЗАО","СЗАО","СЗАО","СЗАО","СЗАО","СЗАО","СЗАО","СЗАО","ЗелАО","ЗелАО","ЗелАО","ЗелАО","ЗелАО"), MATCH($I14, {"Арбат";"Басманный";"Замоскворечье";"Красносельский";"Мещанский";"Пресненский";"Таганский";"Тверской";"Хамовники";"Якиманка";"Аэропорт";"Беговой";"Бескудниковский";"Войковский";"Головинский";"Дегунино Восточное";"Дегунино Западное";"Дмитровский";"Коптево";"Левобережный";"Молжаниновский";"Савеловский";"Сокол";"Тимирязевский";"Ховрино";"Хорошевский";"Алексеевский";"Алтуфьевский";"Бабушкинский";"Бибирево";"Бутырский";"Лианозово";"Лосиноостровский";"Марфино";"Марьина роща";"Медведково Северное";"Медведково Южное";"Останкинский";"Отрадное";"Ростокино";"Свиблово";"Северный";"Ярославский";"Богородское";"Вешняки";"Восточный";"Гольяново";"Ивановское";"Измайлово Восточное";"Измайлово";"Измайлово Северное";"Косино-Ухтомский";"Метрогородок";"Новогиреево";"Новокосино";"Перово";"Преображенское";"Соколиная гора";"Сокольники";"Выхино-Жулебино";"Капотня";"Кузьминки";"Лефортово";"Люблино";"Марьино";"Некрасовка";"Нижегородский";"Печатники";"Рязанский";"Текстильщики";"Южнопортовый";"Бирюлево Восточное";"Бирюлево Западное";"Братеево";"Даниловский";"Донской";"Зябликово";"Москворечье-Сабурово";"Нагатино-Садовники";"Нагатинский затон";"Нагорный";"Орехово-Борисово Северное";"Орехово-Борисово Южное";"Царицыно";"Чертаново Северное";"Чертаново Центральное";"Чертаново Южное";"Академический";"Бутово Северное";"Бутово Южное";"Гагаринский";"Зюзино";"Коньково";"Котловка";"Ломоносовский";"Обручевский";"Теплый Стан";"Черемушки";"Ясенево";"Внуково";"Дорогомилово";"Крылатское";"Кунцево";"Можайский";"Ново-Переделкино";"Очаково-Матвеевское";"Проспект Вернадского";"Раменки";"Солнцево";"Тропарево-Никулино";"Филевский парк";"Фили-Давыдково";"Куркино";"Митино";"Покровское-Стрешнево";"Строгино";"Тушино Северное";"Тушино Южное";"Хорошево-Мневники";"Щукино";"Крюково";"Матушкино";"Савелки";"Силино";"Старое Крюково"}, 0)),"n/a")} -> n/a | M14: =SUBTOTAL(3,M16:M1048576) -> 0 | P14: =IF(ISNUMBER(MATCH(Q14,{"шелфбаннер","разделитель","монетница","чековая лента","воблер","ролл-ап","ролл ап","роллап","roll up","roll-up","rollup","тейбл-тент","тейблтент","лифлет","лифлетинг","семплинг","стойка","стойка с полиграфией","полиграфия","выкладка","сувенирка","топпер","шелфтокер","разделитель","клик-рамка","кликрамка","клик рамка","газетный стенд"},)), "POSm", IF(ISNUMBER(MATCH(Q14,{"LED/LCD","видеокулер 2","навигация интерактивная","медиа фасад","MF","DSS","DCB","DBB","DCF","цифровой экран","экран","монитор","телевизор","LED экран","LED","LCD","digital мобиль","digital-мобиль","digital куб","3D куб","3Д куб","LED куб","3Д конструкция","3D конструкция"},)), "Видео", IF(ISNUMBER(MATCH(Q14,{"автомобиль","машина","выставочное пространство","нестандартная конструкция","подиум","куб","экспозиция","макет","стенд","автостенд","авто стенд","выставочное пространство","выставочные стенды","модульные выставочные стенды","3Д конструкция","3D конструкция"},)), "Экспонирование", IF(ISNUMBER(MATCH(Q14,{"билборд","лифтовая рамка","антивандальный приподъездный стенд","антивандальный подъездный стенд","приподъездный стенд","подъездный стенд","антивандальный лифтовой стенд","лифтовой стенд","антивандальный стенд","брандмауэр","стенд","короб световой","короб световой | лайтбокс","короб световой | кристалайт","кристалайт","короб не световой","короб несветовой","навигация не интерактивная","LB","лайт бокс","лайтбокс","lightbox","короб","рамка","щит","остановка","ситиформат","сити формат","CF","BB","CB","SS","фасад","призматрон","скроллер","стелла","пилон"},)), "Щит", IF(ISNUMBER(MATCH(Q14,{"навигация","подвесной куб","шар","подвесной шар","подвесная фигура","растяжка","шары","флаг","флаги","перетяжка","подвесная 3Д конструкция","подвесная 3D конструкция","подвес"},)), "Подвес", IF(ISNUMBER(MATCH(Q14,{"движущаяся лента","стикер","елочные украшения","елочные шары","шары на елке","ограждение елки","тележка","траволаторы","траволатор","колонны","колонна","окна","окно","межэтажные перекрытия","поверхность","лифтовые шахты","витрины","витрина","револьверные двери","двери слайдер","двери","дверь","лифты","лифт","лестницы","лестница","эскалаторы","эскалатор","наклейка","стикер на стол"},)), "Брендирование/оклейка", IF(ISNUMBER(MATCH(Q14,{"каталог","журнал"},)), "Пресса", ""))))))) | R14: =IF(OR(ISNUMBER(MATCH(Q14,{"экспозиция","макет","стенд","автостенд","авто стенд","выставочное пространство","выставочные стенды","модульные выставочные стенды","3Д конструкция","3D конструкция"},)),P14="Экспонирование"), "нестандартный", IF(ISNUMBER(MATCH(Q14,{"скроллер","призматрон"},)), "динамический", IF(P14="Видео", "цифровой", IF(OR(P14="Пресса",P14="Щит",P14="POSm",P14="Подвес",P14="Брендирование/оклейка"), "статический", "")))) | V14: =IF(P14="Видео", "цифровой постер/ролик", IF(ISNUMBER(MATCH(Q14,{"короб световой","короб световой | лайтбокс","короб световой | кристалайт","лайтбокс","лайт бокс","кристалайт","LB","lightbox"},)), "бэклит", IF(P14="Брендирование/оклейка", "перфарированная пленка/самоклейка", IF(P14="Экспонирование", "под запрос", IF(P14="Подвес", "баннер/ткань", ""))))) | Z14: =SUBTOTAL(9,Z16:Z1048576) -> 0 | AA14: =SUBTOTAL(9,AA16:AA1048576) -> 0 | AB14: =SUBTOTAL(9,AB16:AB1048576) -> 0 | BN14: =SUBTOTAL(9,BN16:BN1048576) -> 0 | BP14: =SUBTOTAL(9,BP16:BP1048576) -> 0 | BQ14: =SUBTOTAL(9,BQ16:BQ1048576) -> 0 | BR14: =SUBTOTAL(9,BR16:BR1048576) -> 0 | BS14: =SUBTOTAL(9,BS16:BS1048576) -> 0 | BT14: =SUBTOTAL(9,BT16:BT1048576) -> 0 | BU14: =SUBTOTAL(9,BU16:BU1048576) -> 0 | BV14: =SUBTOTAL(9,BV16:BV1048576) -> 0 | BW14: =SUBTOTAL(9,BW16:BW1048576) -> 0 | ... CI14: =SUBTOTAL(9,CI16:CI1048576) -> 0 | CK14: =SUBTOTAL(9,CK16:CK1048576) -> 0 | CL14: =SUBTOTAL(9,CL16:CL1048576) -> 0 | CQ14: {=IFERROR( INDEX(CHOOSE( {1,2,3,4,5,6,7,8,9,10,11,12,13,14,15,16}, "в срок не позднее, чем за 30 календарных дней до старта РК","в срок не позднее, чем за 60 календарных дней до старта РК","в срок не позднее, чем за 30 календарных дней до старта РК","уточняется","в срок не позднее, чем за 45 календарных дней до старта РК","уточняется","в срок не позднее, чем за 45 календарных дней до старта РК","в срок не позднее, чем за 30 календарных дней до старта РК","нет данных","в срок не позднее, чем за 45 календарных дней до старта РК","в срок не позднее, чем за 30 календарных дней до старта РК","в срок не позднее, чем за 30 календарных дней до старта РК","в срок не позднее, чем за 45 календарных дней до старта РК","в срок не позднее, чем за 30 календарных дней до старта РК","уточняется"), MATCH(ES14, {"AMS";"RussOutdoor";"HD Outdoor";"Ingroup";"IQ";"Ledproduction";"LisChannel";"Logic";"Media-PPL";"NovikovTV | НовиковТВ";"SMA";"SOK";"КрокусТВ | CrocusTV | IndoorTV";"Сити";"ТЯК Москва"}, 0)),"")} | DB14: =SUBTOTAL(9,DB16:DB1048576) -> 0 | DD14: =SUBTOTAL(9,DD16:DD1048576) -> 0 | DG14: =SUBTOTAL(9,DG16:DG1048576) -> 0 | DI14: =SUBTOTAL(9,DI16:DI1048576) -> 0 | DJ14: =SUBTOTAL(9,DJ16:DJ1048576) -> 0 | DR14: =SUBTOTAL(9,DR16:DR1048576) -> 0 | DS14: =SUBTOTAL(9,DS16:DS1048576) -> 0 | DT14: =SUBTOTAL(9,DT16:DT1048576) -> 0 | DU14: =SUBTOTAL(9,DU16:DU1048576) -> 0 | DV14: =SUBTOTAL(9,DV16:DV1048576) -> 0 | DW14: =SUBTOTAL(9,DW16:DW1048576) -> 0 | DX14: =SUBTOTAL(9,DX16:DX1048576) -> 0 | DY14: =SUBTOTAL(9,DY16:DY1048576) -> 0 | ... EF14: =SUBTOTAL(9,EF16:EF1048576) -> 0 | EH14: =SUBTOTAL(9,EH16:EH1048576) -> 0 | EI14: =SUBTOTAL(9,EI16:EI1048576) -> 0 | EJ14: =SUBTOTAL(9,EJ16:EJ1048576) -> 0 | EK14: =SUBTOTAL(9,EK16:EK1048576) -> 0 | EL14: =SUBTOTAL(9,EL16:EL1048576) -> 0 | EM14: =SUBTOTAL(9,EM16:EM1048576) -> 0 | EN14: =SUBTOTAL(9,EN16:EN1048576) -> 0 | EO14: =SUBTOTAL(9,EO16:EO1048576) -> 0 | ER14: {=IFERROR( INDEX(CHOOSE( {1,2,3,4,5,6,7,8,9,10,11,12,13,14,15,16}, "постоплата 30 календарных дней, после РК, помесячно","постоплата 40 календарных дней, после РК, помесячно","постоплата 30 календарных дней, после РК, помесячно","уточняется","постоплата 30 календарных дней, после РК, помесячно","уточняется","постоплата 30 календарных дней, после РК, помесячно","постоплата не позднее 25 числа месяца размещения","нет данных","постоплата 20 календарных дней, после РК, помесячно","постоплата 30 календарных дней, после РК, помесячно","постоплата 30 календарных дней, после РК, помесячно","100% предоплата, в срок не позднее, чем за 5 календарных дней до старта РК, или по договоренности","уточняется","уточняется"), MATCH(ES14, {"AMS";"RussOutdoor";"HD Outdoor";"Ingroup";"IQ";"Ledproduction";"LisChannel";"Logic";"Media-PPL";"NovikovTV | НовиковТВ";"SMA";"SOK";"КрокусТВ | CrocusTV | IndoorTV";"Сити";"ТЯК Москва"}, 0)),"")} | ET14: {=IFERROR( INDEX(CHOOSE( {1,2,3,4,5,6,7,8,9,10,11,12,13,14,15,16}, "АО АМС Групп","ООО Русс Аутдор","ООО Эйч Ди Аутдор","ООО ИНГРУП","ООО АЙ-КЬЮ ИНТЕРНЕШНЛ","ООО Объединенные Технологии","ООО ФОКС МЕДИА ГРУПП","ООО ЛОДЖИК","ООО Мир рекламы Принт","ООО ПЕЙПЕРФУД ПАБЛИШИНГ","ООО СпортМедиаГрупп","ИП ГОЛОВИН ДМИТРИЙ СЕРГЕЕВИЧ","ООО Международный индор оператор","ПАО СИТИ","ООО ТЦ Москва"), MATCH(ES14, {"AMS";"RussOutdoor";"HD Outdoor";"Ingroup";"IQ";"Ledproduction";"LisChannel";"Logic";"Media-PPL";"NovikovTV | НовиковТВ";"SMA";"SOK";"КрокусТВ | CrocusTV | IndoorTV";"Сити";"ТЯК Москва"}, 0)),"")}
A15: № | B15: Заказчик | C15: Бренд | D15: Округ/регион | E15: Регион/ область | F15: Населенный пункт | G15: Адрес/ маршрут | H15: Округ | I15: Район | J15: Долгота | K15: Широта | L15: Назначение | M15: Наименование | N15: Расположение/ доп.информация | O15: Категория/ Класс/ Средний чек | P15: Тип | Q15: Формат | R15: Вид | S15: Кол-во сторон/ сторона | T15: Описание | U15: Расположение | V15: Материал | W15: Размер, м | X15: Площадь, кв.м | Y15: Разрешение, pix | Z15: Кол-во РН (min) | AA15: Кол-во РН (max) | AB15: Кол-во РН (РК) | AC15: Свет | AD15: Звук | AE15: Фото | AF15: Карта/ Схема/ Локация | AG15: Хронометраж, сек | AH15: Размер блока, сек | AI15: Кол-во выходов в блоке | AJ15: Время работы | AK15: Кол-во часов работы | AL15: Кол-во показов в день | AM15: Кол-во минут в день | AN15: Доля эфира, % | AO15: Кол-во показов за период | AP15: Кол-во минут за период | AQ15: GID | AR15: Трафик, чел./месяц | AS15: OTS, daily | AT15: OTS, month | AU15: GRP | AV15: CPT | AW15: Дата начала | AX15: Дата окончания | AY15: Кол-во дней размещения | AZ15: 45658 | BA15: 45689 | BB15: 45717 | BC15: 45748 | BD15: 45778 | BE15: 45809 | BF15: 45839 | BG15: 45870 | BH15: 45901 | BI15: 45931 | BJ15: 45962 | BK15: 45992 | BL15: МСЯЦЕВ | BM15: ПАКЕТ | BN15: ПРАЙС, стоимость за РАЗМЕЩЕНИЕ за КОЛ-ВО/МЕСЯЦ, руб., NET | BO15: Скидка | BP15: Стоимость за РАЗМЕЩЕНИЕ С УЧЕТОМ СКИДКИ, руб., NET | BQ15: Стоимость за РАЗМЕЩЕНИЕ (ЯНВАРЬ), руб., NET | BR15: Стоимость за РАЗМЕЩЕНИЕ (ФЕВРАЛЬ), руб., NET | BS15: Стоимость за РАЗМЕЩЕНИЕ (МАРТ), руб., NET | BT15: Стоимость за РАЗМЕЩЕНИЕ (АПРЕЛЬ), руб., NET | BU15: Стоимость за РАЗМЕЩЕНИЕ (МАЙ), руб., NET | BV15: Стоимость за РАЗМЕЩЕНИЕ (ИЮНЬ), руб., NET | BW15: Стоимость за РАЗМЕЩЕНИЕ (ИЮЛЬ), руб., NET | BX15: Стоимость за РАЗМЕЩЕНИЕ (АВГУСТ), руб., NET | BY15: Стоимость за РАЗМЕЩЕНИЕ (СЕНТЯБРЬ), руб., NET | BZ15: Стоимость за РАЗМЕЩЕНИЕ (ОКТЯБРЬ), руб., NET | CA15: Стоимость за РАЗМЕЩЕНИЕ (НОЯБРЬ), руб., NET | CB15: Стоимость за РАЗМЕЩЕНИЕ (ДЕКАБРЬ), руб., NET | CC15: ИТОГО стоимость за РАЗМЕЩЕНИЕ, руб., NET | CD15: Единоразовая стоимость за ПРОИЗВОДСТВО за ШТ., руб., NET | CE15: ИТОГО cтоимость за ПРОИЗВОДСТВО, руб., NET | CF15: Единоразовая стоимость за МОНТАЖ, за ШТ., руб., NET | CG15: ИТОГО cтоимость за МОНТАЖ, руб., NET | CH15: ИТОГО за все услуги, руб., NET | CI15: ИТОГО за все услуги, руб., GROSS | CJ15: АК, % | CK15: ВСЕГО, руб., NET | CL15: ВСЕГО, руб., GROSS | CM15: Налог, % | CN15: Форма налогообложения заказчика (УСНО/ОСН) | CO15: Комментарии | CP15: ТТ | CQ15: DL отказа без штрафов | CR15: DL согласования креатива РИМ | CS15: DL предоставления РИМ | CT15: Отчет (объем, форма, сроки) | CV15: СТАТУС | CW15: доп.% | CX15: Юр.лицо агентства | CY15: МАРЖ. за РАЗМЕЩЕНИЕ, % | CZ15: МАРЖ. за ПРОИЗВОДСТВО, % | DA15: МАРЖ. за ДЕ/МОНТАЖ, % | DB15: ВСЕГО МАРЖ., руб., NET | DC15: Кол-во ФО/ месяц | DD15: ПРАЙС стоимость за единоразовый ФО, руб., NET | DE15: % бесплатного ФО | DF15: Частота бесплатного ФО в месяц | DG15: Стоимость за ФО/МЕСЯЦ с учетом % бесплатного ФО, руб., NET | DH15: Тип расчетов стоимости размещения | DI15: БАЗОВЫЙ ПРАЙС, стоимость размещения за КОЛ-ВО/МЕСЯЦ, руб., NET | DJ15: ПРАЙС, стоимость размещения за КОЛ-ВО/МЕСЯЦ+ФО, руб., NET | DK15: Тип расчета итоговой скидки | DL15: Скидка 1 % | DM15: Скидка 2 % | DN15: Скидка 3 % | DO15: Скидка 4 % | DP15: Скидка 5 % | DQ15: ИТОГОВАЯ Скидка | DR15: Стоимость за РАЗМЕЩЕНИЕ С УЧЕТОМ СКИДКИ, руб., NET | DS15: Стоимость за РАЗМЕЩЕНИЕ (ЯНВАРЬ), руб., NET | DT15: Стоимость за РАЗМЕЩЕНИЕ (ФЕВРАЛЬ), руб., NET | DU15: Стоимость за РАЗМЕЩЕНИЕ (МАРТ), руб., NET | DV15: Стоимость за РАЗМЕЩЕНИЕ (АПРЕЛЬ), руб., NET | DW15: Стоимость за РАЗМЕЩЕНИЕ (МАЙ), руб., NET | DX15: Стоимость за РАЗМЕЩЕНИЕ (ИЮНЬ), руб., NET | DY15: Стоимость за РАЗМЕЩЕНИЕ (ИЮЛЬ), руб., NET | DZ15: Стоимость за РАЗМЕЩЕНИЕ (АВГУСТ), руб., NET | EA15: Стоимость за РАЗМЕЩЕНИЕ (СЕНТЯБРЬ), руб., NET | EB15: Стоимость за РАЗМЕЩЕНИЕ (ОКТЯБРЬ), руб., NET | EC15: Стоимость за РАЗМЕЩЕНИЕ (НОЯБРЬ), руб., NET | ED15: Стоимость за РАЗМЕЩЕНИЕ (ДЕКАБРЬ), руб., NET | EE15: ИТОГО стоимость за РАЗМЕЩЕНИЕ, руб., NET | EF15: ИТОГО стоимость за РАЗМЕЩЕНИЕ, руб., GROSS | EG15: Кол-во ПМД | EH15: Единоразовая стоимость за ПРОИЗВОДСТВО за ШТ., руб., NET | EI15: Единоразовая стоимость за ПРОИЗВОДСТВО за КОЛ-ВО, руб., NET | EJ15: ИТОГО стоимость за ПРОИЗВОДСТВО, руб., GROSS | EK15: Единоразовая стоимость за МОНТАЖ, за ШТ., руб., NET | EL15: Единоразовая стоимость за МОНТАЖ, за КОЛ-ВО, руб., NET | EM15: ИТОГО стоимость за МОНТАЖ, руб., GROSS | EN15: ВСЕГО, руб., NET | EO15: ВСЕГО, руб., GROSS | EP15: Налог, % | EQ15: Форма налогообложения поставщика (УСНО/ОСН) | ER15: Условия оплаты | ES15: Подрядчик | ET15: Юр.лицо | EU15: Владение | EV15: Примечание
